Workbook

Sheet 00_Portada
A1: PLAN MAESTRO DE FABRICACIÓN — LÍNEA VOLPAK 4
A2: Presentado por: Sebastian Parra - CC: 1003935397 / Septiembre 2026 · Optimización de secuencia con tiempos de cambio dependientes de la secuencia
B4: EL PROBLEMA
B5: Contexto | C5: Volpak 4 debe fabricar 17 referencias en septiembre de 2026. El modelo minimiza los cambios de referencia con la matriz suministrada y distribuye cartones completos por turno.
B6: Pregunta de decisión | C6: ¿En qué orden y en qué turno debe fabricarse cada producto para cubrir el 100% de la necesidad del mes perdiendo el mínimo tiempo posible en cambios de referencia?
B7: Naturaleza del problema | C7: Es un problema de secuenciación en máquina única con tiempos de preparación dependientes de la secuencia (single-machine scheduling with sequence-dependent setup times). Formalmente equivale a un Problema del Agente Viajero (TSP) de camino abierto.
B9: EL RESULTADO
B10: Secuencia óptima | C10: La secuencia base alcanza la cota inferior de 840 minutos. La prueba verifica los 17 productos y sus transiciones (hoja 06).
B11: Tiempo total de cambio | C11: 840 minutos = 14 horas = 1,75 turnos. Son 7 cambios de 120 min y CERO cambios de 180 min.
B12: Diferencia frente al orden por código | C12: 780 minutos = 13 horas menos de cambios frente a la regla por código. No representa ahorro observado en planta ni ahorro monetario.
B13: Cierre del plan | C13: El caso base termina el 24 de septiembre, en el turno operativo 60. La holgura incluye turnos completos y una fracción del último turno utilizado; consultar hoja 10.
B15: CÓMO LEER ESTE LIBRO
B16: Regla de construcción | C16: Las fórmulas actualizan tiempos y cantidades para estos 17 productos. Si cambia la matriz, volver a ejecutar Solver. Nuevos productos, familias o meses requieren adaptar rangos y calendario.
B17: Hoja principal | C17: 08_PLAN_MAESTRO — la entrega: cantidades a fabricar por producto, turno y día.
B18: Verificación | C18: La hoja 10 comprueba cantidades, capacidad, productos distintos y tiempos. Estos controles no sustituyen validar los supuestos con la planta.
B20: ÍNDICE
B21: 01_Supuestos | C21: Cuatro supuestos operativos y reglas de redondeo y alcance
B22: 02_Datos_Maestros | C22: 17 SKUs: tasa de producción y tiempo unitario
B23: 03_Demanda_ABC | C23: Necesidad del mes, carga en turnos y clasificación ABC
B24: 04_Matriz_Cambios | C24: Matriz 17×17 y agrupación válida para el caso base
B25: 05_Modelo_Solver | C25: Modelo de optimización listo para ejecutar con Solver de Excel
B26: 06_Secuencia_Optima | C26: Solución, prueba de optimalidad y motor de cálculo del plan
B27: 07_Calendario | C27: Malla de turnos de septiembre 2026
B28: 08_PLAN_MAESTRO | C28: ◄ LA ENTREGA: cantidades por producto-turno-día
B29: 09_Detalle_Turnos | C29: Qué ocurre en cada uno de los 74 turnos
B30: 10_KPIs | C30: Indicadores y cuadres de verificación
B31: 11_Sensibilidad | C31: ¿Hasta cuánto crece la demanda antes de romper la capacidad?
B32: 12_Comparativa | C32: Cuánto cuesta secuenciar mal
B33: 13_Info_Adicional | C33: Información adicional requerida para escalar a las demás líneas

Sheet 01_Supuestos
A1: SUPUESTOS DEL MODELO
A2: Todo modelo es una simplificación. Estos son los límites de éste, declarados de frente.
B4: RÉGIMEN DE OPERACIÓN
B5: «En la planta se trabaja de lunes a sábado, cada día tiene tres (3) turnos de 8 horas cada turno y el sábado se trabajan dos (2) turnos (es posible que esto cambie dependiendo de la línea de producción, la cual puede trabajar de domingo a domingo 3 turnos dependiendo del volumen de producción)»
B8: Lo que este libro modela como caso BASE | C8: Exactamente ese régimen: lunes a viernes con 3 turnos de 8 horas (24 horas de operación esos días), sábado con 2 turnos (16 horas), y domingo la línea está DETENIDA — no se programa nada ese día.
B9: Dónde aparece la variante «domingo a domingo» | C9: Únicamente como ESCENARIO DE COMPARACIÓN en la hoja 11_Sensibilidad (3 turnos los 7 días = 90 turnos al mes). No es el plan que se entrega: el plan de la hoja 08 usa siempre el régimen base de arriba.
A11: # | B11: Supuesto | C11: En palabras simples | D11: Formalización técnica | E11: Por qué es razonable | F11: Impacto si no se cumple
A12: 1 | B12: Continuidad y pausas entre turnos | C12: Los cambios pueden continuar en el siguiente turno. La producción se asigna en cartones completos; un cartón no se reparte entre turnos. | D12: Calendario en minutos operativos: los cierres no consumen tiempo de proceso. Se permite retomar lotes y cambios después de una pausa, sin preparación adicional. | E12: Supuesto por confirmar con planta. No implica trabajar domingos ni turnos cerrados. | F12: Si un cartón no cabe al cierre del turno, ese tiempo queda libre. Se registra en la columna AB de la hoja 06. Las tasas del libro deben ser cartones enteros por turno de 8 horas.
A13: 2 | B13: Cada producto se fabrica una sola vez en el mes, de corrido | C13: No se parte la producción de un mismo SKU en varios bloques separados a lo largo del mes: se fabrica toda la necesidad de una vez y se pasa al siguiente producto. | D13: Una sola campaña por producto (sin fraccionar el lote). | E13: Para esta matriz, una secuencia con una campaña por referencia alcanza la cota inferior de cambios. No se generaliza a otras matrices o restricciones. | F13: Si existiera vida útil corta, límite de bodega o fechas de entrega intermedias dentro del mes, habría que fraccionar y el modelo pasaría a ser uno de lotes con capacidad (lot-sizing capacitado, CLSD).
A14: 3 | B14: El mes arranca con la línea «en blanco» | C14: El 1 de septiembre no se sabe (ni se asume) qué se fabricó en agosto, así que el primer producto del mes no paga ningún cambio de referencia. | D14: Línea libre al arrancar el mes: no se hereda montaje del período anterior. | E14: Supuesto optimista por falta de información, pendiente de confirmar; no es una condición observada de la línea. | F14: Si se conociera el último producto fabricado en agosto, ese dato fijaría el punto de partida del recorrido y el costo total podría subir hasta 180 minutos. Es justamente uno de los datos pedidos en la hoja 13.
A15: 4 | B15: La velocidad de cada producto ya es la real, no la de catálogo | C15: Se interpreta cartones/turno como capacidad efectiva de un turno de 8 horas, sin descontar nuevamente pérdidas ya incluidas. | D15: La tasa cartones/turno del archivo maestro se interpreta como producción real esperada, no como capacidad teórica de placa. | E15: Confirmar con planta si la tasa es efectiva o teórica y qué pérdidas contempla. | F15: Si el dato fuera capacidad teórica de máquina, habría que multiplicarlo por el OEE real y toda la carga del mes subiría en la misma proporción. Es otro de los datos pedidos en la hoja 13.

Sheet 02_Datos_Maestros
A1: DATOS MAESTROS DE PRODUCTO
A2: Fuente: «Asignación Productos Linea Fabricación.xlsx» · Línea Volpak 4
A4: Id | B4: Descripción | C4: Línea | D4: Presentación | E4: Formato (gr) | F4: Cartones/Turno | G4: Min/Cartón | H4: Cartones/Hora | I4: Bloque (familia)
A5: 3278 | B5: SALSA MAYONESA (12DP/1/380g) | C5: Volpak 4 | D5: Doypack | E5: 400 | F5: 2460 | G5: =480/F5 -> 0.19512195 | H5: =F5/8 -> 307.5 | I5: =_xlfn.MINIFS('04_Matriz_Cambios'!$B$5:$R$5,'04_Matriz_Cambios'!$B$17:$R$17,0) -> 3278
A6: 3533 | B6: VINAGRE BLANCO (24DP/1/230ml) | C6: Volpak 4 | D6: Doypack | E6: 230 | F6: 1123 | G6: =480/F6 -> 0.42742654 | H6: =F6/8 -> 140.375 | I6: =_xlfn.MINIFS('04_Matriz_Cambios'!$B$5:$R$5,'04_Matriz_Cambios'!$B$22:$R$22,0) -> 3533
A7: 3643 | B7: SALSA ROSADA (12DP/1/380g) | C7: Volpak 4 | D7: Doypack | E7: 400 | F7: 2460 | G7: =480/F7 -> 0.19512195 | H7: =F7/8 -> 307.5 | I7: =_xlfn.MINIFS('04_Matriz_Cambios'!$B$5:$R$5,'04_Matriz_Cambios'!$B$21:$R$21,0) -> 3643
A8: 3749 | B8: SALSA MAYONESA (12DP/1/1000g) | C8: Volpak 4 | D8: Doypack | E8: 1000 | F8: 1352 | G8: =480/F8 -> 0.35502959 | H8: =F8/8 -> 169 | I8: =_xlfn.MINIFS('04_Matriz_Cambios'!$B$5:$R$5,'04_Matriz_Cambios'!$B$16:$R$16,0) -> 3278
A9: 3757 | B9: MOSTANEZA (12DP/1/380g) | C9: Volpak 4 | D9: Doypack | E9: 400 | F9: 2444 | G9: =480/F9 -> 0.19639935 | H9: =F9/8 -> 305.5 | I9: =_xlfn.MINIFS('04_Matriz_Cambios'!$B$5:$R$5,'04_Matriz_Cambios'!$B$6:$R$6,0) -> 3757
A10: 3925 | B10: MOSTANEZA AJO (12DP/1/380g) | C10: Volpak 4 | D10: Doypack | E10: 400 | F10: 2437 | G10: =480/F10 -> 0.19696348 | H10: =F10/8 -> 304.625 | I10: =_xlfn.MINIFS('04_Matriz_Cambios'!$B$5:$R$5,'04_Matriz_Cambios'!$B$7:$R$7,0) -> 3757
A11: 5998 | B11: SALSA DE TOMATE ZEV (20DP/1/500g) | C11: Volpak 4 | D11: Doypack | E11: 500 | F11: 1476 | G11: =480/F11 -> 0.32520325 | H11: =F11/8 -> 184.5 | I11: =_xlfn.MINIFS('04_Matriz_Cambios'!$B$5:$R$5,'04_Matriz_Cambios'!$B$15:$R$15,0) -> 5998
A12: 6616 | B12: MOSTANEZA DEL RANCHO (12DP/1/380g) | C12: Volpak 4 | D12: Doypack | E12: 400 | F12: 2444 | G12: =480/F12 -> 0.19639935 | H12: =F12/8 -> 305.5 | I12: =_xlfn.MINIFS('04_Matriz_Cambios'!$B$5:$R$5,'04_Matriz_Cambios'!$B$8:$R$8,0) -> 3757
A13: 6639 | B13: SALSA BARBECUE (12DP/1/400g) | C13: Volpak 4 | D13: Doypack | E13: 400 | F13: 2493 | G13: =480/F13 -> 0.19253911 | H13: =F13/8 -> 311.625 | I13: =_xlfn.MINIFS('04_Matriz_Cambios'!$B$5:$R$5,'04_Matriz_Cambios'!$B$9:$R$9,0) -> 6639
A14: 6743 | B14: SALSA DE PIÑA (12DP/1/400g) | C14: Volpak 4 | D14: Doypack | E14: 400 | F14: 1502 | G14: =480/F14 -> 0.3195739 | H14: =F14/8 -> 187.75 | I14: =_xlfn.MINIFS('04_Matriz_Cambios'!$B$5:$R$5,'04_Matriz_Cambios'!$B$12:$R$12,0) -> 6743
A15: 7590 | B15: SALSA MAYONESA (12DP/1/600g) | C15: Volpak 4 | D15: Doypack | E15: 600 | F15: 2001 | G15: =480/F15 -> 0.23988006 | H15: =F15/8 -> 250.125 | I15: =_xlfn.MINIFS('04_Matriz_Cambios'!$B$5:$R$5,'04_Matriz_Cambios'!$B$18:$R$18,0) -> 3278
A16: 15564 | B16: SALSA NAPOLITANA (24DP/1/200g) | C16: Volpak 4 | D16: Doypack | E16: 230 | F16: 1684 | G16: =480/F16 -> 0.28503563 | H16: =F16/8 -> 210.5 | I16: =_xlfn.MINIFS('04_Matriz_Cambios'!$B$5:$R$5,'04_Matriz_Cambios'!$B$20:$R$20,0) -> 15564
A17: 15795 | B17: SALSA MAYONESA-V(12DP/1/380g) | C17: Volpak 4 | D17: Doypack | E17: 400 | F17: 2001 | G17: =480/F17 -> 0.23988006 | H17: =F17/8 -> 250.125 | I17: =_xlfn.MINIFS('04_Matriz_Cambios'!$B$5:$R$5,'04_Matriz_Cambios'!$B$19:$R$19,0) -> 3278
A18: 15881 | B18: SALSA DE TOMATE SAVORIA (12DP/1/500g) | C18: Volpak 4 | D18: Doypack | E18: 500 | F18: 1476 | G18: =480/F18 -> 0.32520325 | H18: =F18/8 -> 184.5 | I18: =_xlfn.MINIFS('04_Matriz_Cambios'!$B$5:$R$5,'04_Matriz_Cambios'!$B$14:$R$14,0) -> 5998
A19: 16787 | B19: SALSA DE TOMATE SAVORIA (12DP/1/1000g) | C19: Volpak 4 | D19: Doypack | E19: 1000 | F19: 1686 | G19: =480/F19 -> 0.28469751 | H19: =F19/8 -> 210.75 | I19: =_xlfn.MINIFS('04_Matriz_Cambios'!$B$5:$R$5,'04_Matriz_Cambios'!$B$13:$R$13,0) -> 5998
A20: 16816 | B20: SALSA DE MAYONESA ZEV (24DP/1/400G) | C20: Volpak 4 | D20: Doypack | E20: 400 | F20: 1200 | G20: =480/F20 -> 0.4 | H20: =F20/8 -> 150 | I20: =_xlfn.MINIFS('04_Matriz_Cambios'!$B$5:$R$5,'04_Matriz_Cambios'!$B$11:$R$11,0) -> 3278
A21: 17246 | B21: SALSA DE MAYONESA LINE (21DP/1/500G) | C21: Volpak 4 | D21: Doypack | E21: 500 | F21: 1144 | G21: =480/F21 -> 0.41958042 | H21: =F21/8 -> 143 | I21: =_xlfn.MINIFS('04_Matriz_Cambios'!$B$5:$R$5,'04_Matriz_Cambios'!$B$10:$R$10,0) -> 3278
A23: Nota: | B23: La columna «Bloque» NO está digitada: se deduce con MINIFS sobre la matriz de cambios. Devuelve el menor Id con el que el producto tiene cambio de 0 minutos, que identifica su familia tecnológica.

Sheet 03_Demanda_ABC
A1: NECESIDAD DE FABRICACIÓN Y CLASIFICACIÓN ABC
A2: Fuente: «Necesidad Fabricación Septiembre 2026.xlsx» · La carga se mide en TURNOS, no en cartones: 1.000 cartones de un SKU lento pesan más que 1.000 de uno rápido.
A4: Id | B4: Descripción | C4: Necesidad (cartones) | D4: Cartones/Turno | E4: Turnos requeridos | F4: Minutos requeridos | G4: % carga | H4: % acumulado | I4: Clase ABC
A5: 16816 | B5: =IFERROR(INDEX('02_Datos_Maestros'!$B$5:$B$21,MATCH($A5,'02_Datos_Maestros'!$A$5:$A$21,0)),"") -> SALSA DE MAYONESA ZEV (24DP/1/400G) | C5: 19200 | D5: =INDEX('02_Datos_Maestros'!$F$5:$F$21,MATCH($A5,'02_Datos_Maestros'!$A$5:$A$21,0)) -> 1200 | E5: =C5/D5 -> 16 | F5: =E5*480 -> 7680 | G5: =E5/SUM($E$5:$E$21) -> 0.27606411 | H5: =SUM($G$5:G5) -> 0.27606411 | I5: =IF(H5<=0.8,"A",IF(H5<=0.95,"B","C")) -> A
A6: 5998 | B6: =IFERROR(INDEX('02_Datos_Maestros'!$B$5:$B$21,MATCH($A6,'02_Datos_Maestros'!$A$5:$A$21,0)),"") -> SALSA DE TOMATE ZEV (20DP/1/500g) | C6: 20286 | D6: =INDEX('02_Datos_Maestros'!$F$5:$F$21,MATCH($A6,'02_Datos_Maestros'!$A$5:$A$21,0)) -> 1476 | E6: =C6/D6 -> 13.743902 | F6: =E6*480 -> 6597.0732 | G6: =E6/SUM($E$5:$E$21) -> 0.23713738 | H6: =SUM($G$5:G6) -> 0.51320149 | I6: =IF(H6<=0.8,"A",IF(H6<=0.95,"B","C")) -> A
A7: 17246 | B7: =IFERROR(INDEX('02_Datos_Maestros'!$B$5:$B$21,MATCH($A7,'02_Datos_Maestros'!$A$5:$A$21,0)),"") -> SALSA DE MAYONESA LINE (21DP/1/500G) | C7: 7200 | D7: =INDEX('02_Datos_Maestros'!$F$5:$F$21,MATCH($A7,'02_Datos_Maestros'!$A$5:$A$21,0)) -> 1144 | E7: =C7/D7 -> 6.2937063 | F7: =E7*480 -> 3020.979 | G7: =E7/SUM($E$5:$E$21) -> 0.10859165 | H7: =SUM($G$5:G7) -> 0.62179314 | I7: =IF(H7<=0.8,"A",IF(H7<=0.95,"B","C")) -> A
A8: 3533 | B8: =IFERROR(INDEX('02_Datos_Maestros'!$B$5:$B$21,MATCH($A8,'02_Datos_Maestros'!$A$5:$A$21,0)),"") -> VINAGRE BLANCO (24DP/1/230ml) | C8: 3834 | D8: =INDEX('02_Datos_Maestros'!$F$5:$F$21,MATCH($A8,'02_Datos_Maestros'!$A$5:$A$21,0)) -> 1123 | E8: =C8/D8 -> 3.4140695 | F8: =E8*480 -> 1638.7533 | G8: =E8/SUM($E$5:$E$21) -> 0.058906377 | H8: =SUM($G$5:G8) -> 0.68069952 | I8: =IF(H8<=0.8,"A",IF(H8<=0.95,"B","C")) -> A
A9: 3749 | B9: =IFERROR(INDEX('02_Datos_Maestros'!$B$5:$B$21,MATCH($A9,'02_Datos_Maestros'!$A$5:$A$21,0)),"") -> SALSA MAYONESA (12DP/1/1000g) | C9: 4440 | D9: =INDEX('02_Datos_Maestros'!$F$5:$F$21,MATCH($A9,'02_Datos_Maestros'!$A$5:$A$21,0)) -> 1352 | E9: =C9/D9 -> 3.2840237 | F9: =E9*480 -> 1576.3314 | G9: =E9/SUM($E$5:$E$21) -> 0.056662566 | H9: =SUM($G$5:G9) -> 0.73736208 | I9: =IF(H9<=0.8,"A",IF(H9<=0.95,"B","C")) -> A
A10: 3278 | B10: =IFERROR(INDEX('02_Datos_Maestros'!$B$5:$B$21,MATCH($A10,'02_Datos_Maestros'!$A$5:$A$21,0)),"") -> SALSA MAYONESA (12DP/1/380g) | C10: 6206 | D10: =INDEX('02_Datos_Maestros'!$F$5:$F$21,MATCH($A10,'02_Datos_Maestros'!$A$5:$A$21,0)) -> 2460 | E10: =C10/D10 -> 2.5227642 | F10: =E10*480 -> 1210.9268 | G10: =E10/SUM($E$5:$E$21) -> 0.043527791 | H10: =SUM($G$5:G10) -> 0.78088987 | I10: =IF(H10<=0.8,"A",IF(H10<=0.95,"B","C")) -> A
A11: 15881 | B11: =IFERROR(INDEX('02_Datos_Maestros'!$B$5:$B$21,MATCH($A11,'02_Datos_Maestros'!$A$5:$A$21,0)),"") -> SALSA DE TOMATE SAVORIA (12DP/1/500g) | C11: 3540 | D11: =INDEX('02_Datos_Maestros'!$F$5:$F$21,MATCH($A11,'02_Datos_Maestros'!$A$5:$A$21,0)) -> 1476 | E11: =C11/D11 -> 2.398374 | F11: =E11*480 -> 1151.2195 | G11: =E11/SUM($E$5:$E$21) -> 0.041381561 | H11: =SUM($G$5:G11) -> 0.82227143 | I11: =IF(H11<=0.8,"A",IF(H11<=0.95,"B","C")) -> B
A12: 6743 | B12: =IFERROR(INDEX('02_Datos_Maestros'!$B$5:$B$21,MATCH($A12,'02_Datos_Maestros'!$A$5:$A$21,0)),"") -> SALSA DE PIÑA (12DP/1/400g) | C12: 2754 | D12: =INDEX('02_Datos_Maestros'!$F$5:$F$21,MATCH($A12,'02_Datos_Maestros'!$A$5:$A$21,0)) -> 1502 | E12: =C12/D12 -> 1.8335553 | F12: =E12*480 -> 880.10652 | G12: =E12/SUM($E$5:$E$21) -> 0.031636175 | H12: =SUM($G$5:G12) -> 0.85390761 | I12: =IF(H12<=0.8,"A",IF(H12<=0.95,"B","C")) -> B
A13: 3757 | B13: =IFERROR(INDEX('02_Datos_Maestros'!$B$5:$B$21,MATCH($A13,'02_Datos_Maestros'!$A$5:$A$21,0)),"") -> MOSTANEZA (12DP/1/380g) | C13: 3600 | D13: =INDEX('02_Datos_Maestros'!$F$5:$F$21,MATCH($A13,'02_Datos_Maestros'!$A$5:$A$21,0)) -> 2444 | E13: =C13/D13 -> 1.4729951 | F13: =E13*480 -> 707.03764 | G13: =E13/SUM($E$5:$E$21) -> 0.025415067 | H13: =SUM($G$5:G13) -> 0.87932267 | I13: =IF(H13<=0.8,"A",IF(H13<=0.95,"B","C")) -> B
A14: 3643 | B14: =IFERROR(INDEX('02_Datos_Maestros'!$B$5:$B$21,MATCH($A14,'02_Datos_Maestros'!$A$5:$A$21,0)),"") -> SALSA ROSADA (12DP/1/380g) | C14: 3220 | D14: =INDEX('02_Datos_Maestros'!$F$5:$F$21,MATCH($A14,'02_Datos_Maestros'!$A$5:$A$21,0)) -> 2460 | E14: =C14/D14 -> 1.3089431 | F14: =E14*480 -> 628.29268 | G14: =E14/SUM($E$5:$E$21) -> 0.022584513 | H14: =SUM($G$5:G14) -> 0.90190719 | I14: =IF(H14<=0.8,"A",IF(H14<=0.95,"B","C")) -> B
A15: 6639 | B15: =IFERROR(INDEX('02_Datos_Maestros'!$B$5:$B$21,MATCH($A15,'02_Datos_Maestros'!$A$5:$A$21,0)),"") -> SALSA BARBECUE (12DP/1/400g) | C15: 2900 | D15: =INDEX('02_Datos_Maestros'!$F$5:$F$21,MATCH($A15,'02_Datos_Maestros'!$A$5:$A$21,0)) -> 2493 | E15: =C15/D15 -> 1.1632571 | F15: =E15*480 -> 558.36342 | G15: =E15/SUM($E$5:$E$21) -> 0.020070846 | H15: =SUM($G$5:G15) -> 0.92197803 | I15: =IF(H15<=0.8,"A",IF(H15<=0.95,"B","C")) -> B
A16: 15564 | B16: =IFERROR(INDEX('02_Datos_Maestros'!$B$5:$B$21,MATCH($A16,'02_Datos_Maestros'!$A$5:$A$21,0)),"") -> SALSA NAPOLITANA (24DP/1/200g) | C16: 1840 | D16: =INDEX('02_Datos_Maestros'!$F$5:$F$21,MATCH($A16,'02_Datos_Maestros'!$A$5:$A$21,0)) -> 1684 | E16: =C16/D16 -> 1.0926366 | F16: =E16*480 -> 524.46556 | G16: =E16/SUM($E$5:$E$21) -> 0.018852359 | H16: =SUM($G$5:G16) -> 0.94083039 | I16: =IF(H16<=0.8,"A",IF(H16<=0.95,"B","C")) -> B
... A21: 16787 | B21: =IFERROR(INDEX('02_Datos_Maestros'!$B$5:$B$21,MATCH($A21,'02_Datos_Maestros'!$A$5:$A$21,0)),"") -> SALSA DE TOMATE SAVORIA (12DP/1/1000g) | C21: 1000 | D21: =INDEX('02_Datos_Maestros'!$F$5:$F$21,MATCH($A21,'02_Datos_Maestros'!$A$5:$A$21,0)) -> 1686 | E21: =C21/D21 -> 0.59311981 | F21: =E21*480 -> 284.69751 | G21: =E21/SUM($E$5:$E$21) -> 0.010233693 | H21: =SUM($G$5:G21) -> 1 | I21: =IF(H21<=0.8,"A",IF(H21<=0.95,"B","C")) -> C
B22: TOTAL | C22: =SUM(C5:C21) -> 86331 | E22: =SUM(E5:E21) -> 57.957553 | F22: =SUM(F5:F21) -> 27819.625 | G22: =SUM(G5:G21) -> 1

Sheet 04_Matriz_Cambios
A1: MATRIZ DE TIEMPOS DE CAMBIO (minutos)
A2: Fuente: Matriz Tiempos Cambio.xlsx. Se interpreta fila = salida, columna = entrada y unidad = minutos; confirmar con planta.
A4: De \ A | B4: 3757 | C4: 3925 | D4: 6616 | E4: 6639 | F4: 17246 | G4: 16816 | H4: 6743 | I4: 16787 | J4: 15881 | K4: 5998 | L4: 3749 | M4: 3278 | N4: 7590 | O4: 15795 | P4: 15564 | Q4: 3643 | R4: 3533
A5: (vector Id) | B5: 3757 | C5: 3925 | D5: 6616 | E5: 6639 | F5: 17246 | G5: 16816 | H5: 6743 | I5: 16787 | J5: 15881 | K5: 5998 | L5: 3749 | M5: 3278 | N5: 7590 | O5: 15795 | P5: 15564 | Q5: 3643 | R5: 3533
A6: 3757 | B6: 0 | C6: 0 | D6: 0 | E6: 180 | F6: 120 | G6: 120 | H6: 180 | I6: 120 | J6: 120 | K6: 120 | L6: 120 | M6: 120 | N6: 120 | O6: 120 | P6: 180 | Q6: 180 | R6: 120
A7: 3925 | B7: 0 | C7: 0 | D7: 0 | E7: 180 | F7: 120 | G7: 120 | H7: 180 | I7: 120 | J7: 120 | K7: 120 | L7: 120 | M7: 120 | N7: 120 | O7: 120 | P7: 180 | Q7: 180 | R7: 120
A8: 6616 | B8: 0 | C8: 0 | D8: 0 | E8: 180 | F8: 120 | G8: 120 | H8: 180 | I8: 120 | J8: 120 | K8: 120 | L8: 120 | M8: 120 | N8: 120 | O8: 120 | P8: 180 | Q8: 180 | R8: 120
A9: 6639 | B9: 180 | C9: 180 | D9: 180 | E9: 0 | F9: 180 | G9: 120 | H9: 120 | I9: 120 | J9: 120 | K9: 120 | L9: 120 | M9: 120 | N9: 120 | O9: 120 | P9: 120 | Q9: 120 | R9: 120
A10: 17246 | B10: 120 | C10: 120 | D10: 120 | E10: 180 | F10: 0 | G10: 0 | H10: 180 | I10: 120 | J10: 120 | K10: 120 | L10: 0 | M10: 0 | N10: 0 | O10: 0 | P10: 120 | Q10: 120 | R10: 120
A11: 16816 | B11: 120 | C11: 120 | D11: 120 | E11: 120 | F11: 0 | G11: 0 | H11: 180 | I11: 120 | J11: 120 | K11: 120 | L11: 0 | M11: 0 | N11: 0 | O11: 0 | P11: 120 | Q11: 120 | R11: 120
A12: 6743 | B12: 180 | C12: 180 | D12: 180 | E12: 120 | F12: 180 | G12: 180 | H12: 0 | I12: 120 | J12: 120 | K12: 120 | L12: 120 | M12: 120 | N12: 120 | O12: 120 | P12: 120 | Q12: 120 | R12: 120
A13: 16787 | B13: 120 | C13: 120 | D13: 120 | E13: 120 | F13: 120 | G13: 120 | H13: 120 | I13: 0 | J13: 0 | K13: 0 | L13: 120 | M13: 120 | N13: 120 | O13: 120 | P13: 120 | Q13: 120 | R13: 120
A14: 15881 | B14: 120 | C14: 120 | D14: 120 | E14: 120 | F14: 120 | G14: 120 | H14: 120 | I14: 0 | J14: 0 | K14: 0 | L14: 120 | M14: 120 | N14: 120 | O14: 120 | P14: 120 | Q14: 120 | R14: 120
A15: 5998 | B15: 120 | C15: 120 | D15: 120 | E15: 120 | F15: 120 | G15: 120 | H15: 120 | I15: 0 | J15: 0 | K15: 0 | L15: 120 | M15: 120 | N15: 120 | O15: 120 | P15: 120 | Q15: 120 | R15: 120
A16: 3749 | B16: 120 | C16: 120 | D16: 120 | E16: 120 | F16: 0 | G16: 0 | H16: 120 | I16: 120 | J16: 120 | K16: 120 | L16: 0 | M16: 0 | N16: 0 | O16: 0 | P16: 120 | Q16: 120 | R16: 120
A17: 3278 | B17: 120 | C17: 120 | D17: 120 | E17: 120 | F17: 0 | G17: 0 | H17: 120 | I17: 120 | J17: 120 | K17: 120 | L17: 0 | M17: 0 | N17: 0 | O17: 0 | P17: 120 | Q17: 120 | R17: 120
... A22: 3533 | B22: 120 | C22: 120 | D22: 120 | E22: 120 | F22: 120 | G22: 120 | H22: 120 | I22: 120 | J22: 120 | K22: 120 | L22: 120 | M22: 120 | N22: 120 | O22: 120 | P22: 120 | Q22: 120 | R22: 0
A24: LECTURA DEL DATO
A25: Simetría | B25: La matriz es perfectamente simétrica: cambiar de A a B cuesta lo mismo que de B a A. Esto permite tratar el problema como un TSP simétrico (más fácil de resolver que el asimétrico).
A26: Valores | B26: Los datos toman valores 0, 120 y 180. Hay 30 transiciones dirigidas de 180 minutos (15 pares simétricos). No se ha confirmado qué actividades incluye cada cambio.
A27: Grupos | B27: En el caso base hay ocho grupos completos con cambios internos de cero. Su orden interno puede afectar el costo de entrada o salida del grupo.
A28: Alcance | B28: La agrupación permite una cota inferior y un modelo reducido para este caso. El costo mínimo entre grupos debe comprobarse en la secuencia expandida de productos; no basta el costo agregado.
A30: FAMILIAS DETECTADAS
A31: Bloque | B31: Nombre | C31: Productos | L31: N°
A32: B1 | B32: F1 Mostazas | C32: 3757, 3925, 6616 | L32: 3
A33: B2 | B33: S1 Barbecue | C33: 6639 | L33: 1
A34: B3 | B34: F2 Emulsiones | C34: 17246, 16816, 3749, 3278, 7590, 15795 | L34: 6
A35: B4 | B35: S2 Piña | C35: 6743 | L35: 1
A36: B5 | B36: F3 Tomate | C36: 16787, 15881, 5998 | L36: 3
A37: B6 | B37: S3 Napolitana | C37: 15564 | L37: 1
A38: B7 | B38: S4 Rosada | C38: 3643 | L38: 1
A39: B8 | B39: S5 Vinagre | C39: 3533 | L39: 1

Sheet 05_Modelo_Solver
A1: MODELO DE OPTIMIZACIÓN — TSP DE CAMINO ABIERTO
A2: Modelo reducido para las ocho familias del caso base. Ejecutar Solver con todas las restricciones, incluida la diagonal cero. Verificar después la secuencia de los 17 productos.
S4: FORMULACIÓN MATEMÁTICA
A5: CELDA OBJETIVO (minimizar) | S5: CONJUNTOS
A6: Z = Σ d(i,j)·x(i,j) | C6: =SUMPRODUCT($F$11:$N$19,$F$26:$N$34) -> 840 | S6: N = {0,1,…,8} nodos (0 = origen ficticio, 1-8 = bloques)
A7: Cota inferior teórica | C7: =(COUNTA($B$12:$B$19)-1)*_xlfn.MINIFS($F$11:$N$19,$F$11:$N$19,">0") -> 840
A8: ¿Solución = cota inferior? | C8: =IF(AND(ABS($C$6-$C$7)<0.000001,$E$51=0,$E$50<=8,COUNTIF($O$26:$O$34,1)=9,COUNTIF($F$35:$N$35,1)=9),"Alcanza cota; verificar productos","REVISAR") -> Alcanza cota; verificar productos | S8: PARÁMETROS
S9: d(i,j) = tiempo mínimo de cambio entre el bloque i y el j
A10: Nodo | B10: Bloque | C10: Rep. Id | E10: d(i,j) | F10: 0 | G10: 1 | H10: 2 | I10: 3 | J10: 4 | K10: 5 | L10: 6 | M10: 7 | N10: 8 | S10: d(0,j) = d(i,0) = 0 (el origen ficticio no cuesta)
A11: 0 | B11: (origen ficticio) | C11: — | E11: 0 | F11: 0 | G11: 0 | H11: 0 | I11: 0 | J11: 0 | K11: 0 | L11: 0 | M11: 0 | N11: 0
A12: 1 | B12: F1 Mostazas | C12: 3757 | E12: 1 | F12: 0 | G12: 0 | H12: =_xlfn.MINIFS($C$200:$C$488,$D$200:$D$488,$C$12,$E$200:$E$488,$C$13) -> 180 | I12: =_xlfn.MINIFS($C$200:$C$488,$D$200:$D$488,$C$12,$E$200:$E$488,$C$14) -> 120 | J12: =_xlfn.MINIFS($C$200:$C$488,$D$200:$D$488,$C$12,$E$200:$E$488,$C$15) -> 180 | K12: =_xlfn.MINIFS($C$200:$C$488,$D$200:$D$488,$C$12,$E$200:$E$488,$C$16) -> 120 | L12: =_xlfn.MINIFS($C$200:$C$488,$D$200:$D$488,$C$12,$E$200:$E$488,$C$17) -> 180 | M12: =_xlfn.MINIFS($C$200:$C$488,$D$200:$D$488,$C$12,$E$200:$E$488,$C$18) -> 180 | N12: =_xlfn.MINIFS($C$200:$C$488,$D$200:$D$488,$C$12,$E$200:$E$488,$C$19) -> 120 | S12: VARIABLES DE DECISIÓN
A13: 2 | B13: S1 Barbecue | C13: 6639 | E13: 2 | F13: 0 | G13: =_xlfn.MINIFS($C$200:$C$488,$D$200:$D$488,$C$13,$E$200:$E$488,$C$12) -> 180 | H13: 0 | I13: =_xlfn.MINIFS($C$200:$C$488,$D$200:$D$488,$C$13,$E$200:$E$488,$C$14) -> 120 | J13: =_xlfn.MINIFS($C$200:$C$488,$D$200:$D$488,$C$13,$E$200:$E$488,$C$15) -> 120 | K13: =_xlfn.MINIFS($C$200:$C$488,$D$200:$D$488,$C$13,$E$200:$E$488,$C$16) -> 120 | L13: =_xlfn.MINIFS($C$200:$C$488,$D$200:$D$488,$C$13,$E$200:$E$488,$C$17) -> 120 | M13: =_xlfn.MINIFS($C$200:$C$488,$D$200:$D$488,$C$13,$E$200:$E$488,$C$18) -> 120 | N13: =_xlfn.MINIFS($C$200:$C$488,$D$200:$D$488,$C$13,$E$200:$E$488,$C$19) -> 120 | S13: x(i,j) ∈ {0,1} 1 si tras el bloque i se fabrica el bloque j
A14: 3 | B14: F2 Emulsiones | C14: 3278 | E14: 3 | F14: 0 | G14: =_xlfn.MINIFS($C$200:$C$488,$D$200:$D$488,$C$14,$E$200:$E$488,$C$12) -> 120 | H14: =_xlfn.MINIFS($C$200:$C$488,$D$200:$D$488,$C$14,$E$200:$E$488,$C$13) -> 120 | I14: 0 | J14: =_xlfn.MINIFS($C$200:$C$488,$D$200:$D$488,$C$14,$E$200:$E$488,$C$15) -> 120 | K14: =_xlfn.MINIFS($C$200:$C$488,$D$200:$D$488,$C$14,$E$200:$E$488,$C$16) -> 120 | L14: =_xlfn.MINIFS($C$200:$C$488,$D$200:$D$488,$C$14,$E$200:$E$488,$C$17) -> 120 | M14: =_xlfn.MINIFS($C$200:$C$488,$D$200:$D$488,$C$14,$E$200:$E$488,$C$18) -> 120 | N14: =_xlfn.MINIFS($C$200:$C$488,$D$200:$D$488,$C$14,$E$200:$E$488,$C$19) -> 120 | S14: u(i) ∈ [1,8] posición del bloque i en la secuencia
A15: 4 | B15: S2 Piña | C15: 6743 | E15: 4 | F15: 0 | G15: =_xlfn.MINIFS($C$200:$C$488,$D$200:$D$488,$C$15,$E$200:$E$488,$C$12) -> 180 | H15: =_xlfn.MINIFS($C$200:$C$488,$D$200:$D$488,$C$15,$E$200:$E$488,$C$13) -> 120 | I15: =_xlfn.MINIFS($C$200:$C$488,$D$200:$D$488,$C$15,$E$200:$E$488,$C$14) -> 120 | J15: 0 | K15: =_xlfn.MINIFS($C$200:$C$488,$D$200:$D$488,$C$15,$E$200:$E$488,$C$16) -> 120 | L15: =_xlfn.MINIFS($C$200:$C$488,$D$200:$D$488,$C$15,$E$200:$E$488,$C$17) -> 120 | M15: =_xlfn.MINIFS($C$200:$C$488,$D$200:$D$488,$C$15,$E$200:$E$488,$C$18) -> 120 | N15: =_xlfn.MINIFS($C$200:$C$488,$D$200:$D$488,$C$15,$E$200:$E$488,$C$19) -> 120
A16: 5 | B16: F3 Tomate | C16: 5998 | E16: 5 | F16: 0 | G16: =_xlfn.MINIFS($C$200:$C$488,$D$200:$D$488,$C$16,$E$200:$E$488,$C$12) -> 120 | H16: =_xlfn.MINIFS($C$200:$C$488,$D$200:$D$488,$C$16,$E$200:$E$488,$C$13) -> 120 | I16: =_xlfn.MINIFS($C$200:$C$488,$D$200:$D$488,$C$16,$E$200:$E$488,$C$14) -> 120 | J16: =_xlfn.MINIFS($C$200:$C$488,$D$200:$D$488,$C$16,$E$200:$E$488,$C$15) -> 120 | K16: 0 | L16: =_xlfn.MINIFS($C$200:$C$488,$D$200:$D$488,$C$16,$E$200:$E$488,$C$17) -> 120 | M16: =_xlfn.MINIFS($C$200:$C$488,$D$200:$D$488,$C$16,$E$200:$E$488,$C$18) -> 120 | N16: =_xlfn.MINIFS($C$200:$C$488,$D$200:$D$488,$C$16,$E$200:$E$488,$C$19) -> 120 | S16: FUNCIÓN OBJETIVO
A17: 6 | B17: S3 Napolitana | C17: 15564 | E17: 6 | F17: 0 | G17: =_xlfn.MINIFS($C$200:$C$488,$D$200:$D$488,$C$17,$E$200:$E$488,$C$12) -> 180 | H17: =_xlfn.MINIFS($C$200:$C$488,$D$200:$D$488,$C$17,$E$200:$E$488,$C$13) -> 120 | I17: =_xlfn.MINIFS($C$200:$C$488,$D$200:$D$488,$C$17,$E$200:$E$488,$C$14) -> 120 | J17: =_xlfn.MINIFS($C$200:$C$488,$D$200:$D$488,$C$17,$E$200:$E$488,$C$15) -> 120 | K17: =_xlfn.MINIFS($C$200:$C$488,$D$200:$D$488,$C$17,$E$200:$E$488,$C$16) -> 120 | L17: 0 | M17: =_xlfn.MINIFS($C$200:$C$488,$D$200:$D$488,$C$17,$E$200:$E$488,$C$18) -> 120 | N17: =_xlfn.MINIFS($C$200:$C$488,$D$200:$D$488,$C$17,$E$200:$E$488,$C$19) -> 120 | S17: Min Z = Σi Σj d(i,j) · x(i,j)
A18: 7 | B18: S4 Rosada | C18: 3643 | E18: 7 | F18: 0 | G18: =_xlfn.MINIFS($C$200:$C$488,$D$200:$D$488,$C$18,$E$200:$E$488,$C$12) -> 180 | H18: =_xlfn.MINIFS($C$200:$C$488,$D$200:$D$488,$C$18,$E$200:$E$488,$C$13) -> 120 | I18: =_xlfn.MINIFS($C$200:$C$488,$D$200:$D$488,$C$18,$E$200:$E$488,$C$14) -> 120 | J18: =_xlfn.MINIFS($C$200:$C$488,$D$200:$D$488,$C$18,$E$200:$E$488,$C$15) -> 120 | K18: =_xlfn.MINIFS($C$200:$C$488,$D$200:$D$488,$C$18,$E$200:$E$488,$C$16) -> 120 | L18: =_xlfn.MINIFS($C$200:$C$488,$D$200:$D$488,$C$18,$E$200:$E$488,$C$17) -> 120 | M18: 0 | N18: =_xlfn.MINIFS($C$200:$C$488,$D$200:$D$488,$C$18,$E$200:$E$488,$C$19) -> 120
A19: 8 | B19: S5 Vinagre | C19: 3533 | E19: 8 | F19: 0 | G19: =_xlfn.MINIFS($C$200:$C$488,$D$200:$D$488,$C$19,$E$200:$E$488,$C$12) -> 120 | H19: =_xlfn.MINIFS($C$200:$C$488,$D$200:$D$488,$C$19,$E$200:$E$488,$C$13) -> 120 | I19: =_xlfn.MINIFS($C$200:$C$488,$D$200:$D$488,$C$19,$E$200:$E$488,$C$14) -> 120 | J19: =_xlfn.MINIFS($C$200:$C$488,$D$200:$D$488,$C$19,$E$200:$E$488,$C$15) -> 120 | K19: =_xlfn.MINIFS($C$200:$C$488,$D$200:$D$488,$C$19,$E$200:$E$488,$C$16) -> 120 | L19: =_xlfn.MINIFS($C$200:$C$488,$D$200:$D$488,$C$19,$E$200:$E$488,$C$17) -> 120 | M19: =_xlfn.MINIFS($C$200:$C$488,$D$200:$D$488,$C$19,$E$200:$E$488,$C$18) -> 120 | N19: 0 | S19: SUJETO A
S20: (1) Σj x(i,j) = 1 ∀i de cada bloque se sale una vez
S21: (2) Σi x(i,j) = 1 ∀j a cada bloque se entra una vez
S22: (3) x(i,i) = 0 ∀i sin autolazos
S23: (4) u(i) − u(j) + 9·x(i,j) ≤ 8 ∀i,j ≥ 1, i≠j (MTZ: prohíbe subtoures)
A24: VARIABLES DE DECISIÓN x(i,j) — celdas amarillas | S24: (5) x(i,j) binaria, u(i) entera
E25: x(i,j) | F25: 0 | G25: 1 | H25: 2 | I25: 3 | J25: 4 | K25: 5 | L25: 6 | M25: 7 | N25: 8 | O25: Σ fila | P25: = | Q25: u(i)
E26: 0 | F26: 0 | G26: 0 | H26: 0 | I26: 0 | J26: 0 | K26: 0 | L26: 0 | M26: 0 | N26: 1 | O26: =SUM(F26:N26) -> 1 | P26: 1 | Q26: 0 | S26: POR QUÉ EL NODO FICTICIO
E27: 1 | F27: 1 | G27: 0 | H27: 0 | I27: 0 | J27: 0 | K27: 0 | L27: 0 | M27: 0 | N27: 0 | O27: =SUM(F27:N27) -> 1 | P27: 1 | Q27: 8 | S27: El TSP clásico busca un CICLO cerrado, pero un plan de producción
E28: 2 | F28: 0 | G28: 0 | H28: 0 | I28: 1 | J28: 0 | K28: 0 | L28: 0 | M28: 0 | N28: 0 | O28: =SUM(F28:N28) -> 1 | P28: 1 | Q28: 6 | S28: es un CAMINO: se arranca en un producto y se termina en otro, sin
E29: 3 | F29: 0 | G29: 1 | H29: 0 | I29: 0 | J29: 0 | K29: 0 | L29: 0 | M29: 0 | N29: 0 | O29: =SUM(F29:N29) -> 1 | P29: 1 | Q29: 7 | S29: volver al inicio. Se añade un nodo 0 a distancia cero de todos:
E30: 4 | F30: 0 | G30: 0 | H30: 1 | I30: 0 | J30: 0 | K30: 0 | L30: 0 | M30: 0 | N30: 0 | O30: =SUM(F30:N30) -> 1 | P30: 1 | Q30: 5 | S30: el ciclo óptimo sobre 9 nodos equivale al camino óptimo sobre 8.
E31: 5 | F31: 0 | G31: 0 | H31: 0 | I31: 0 | J31: 1 | K31: 0 | L31: 0 | M31: 0 | N31: 0 | O31: =SUM(F31:N31) -> 1 | P31: 1 | Q31: 4
E32: 6 | F32: 0 | G32: 0 | H32: 0 | I32: 0 | J32: 0 | K32: 1 | L32: 0 | M32: 0 | N32: 0 | O32: =SUM(F32:N32) -> 1 | P32: 1 | Q32: 3 | S32: POR QUÉ 8 NODOS Y NO 17
E33: 7 | F33: 0 | G33: 0 | H33: 0 | I33: 0 | J33: 0 | K33: 0 | L33: 1 | M33: 0 | N33: 0 | O33: =SUM(F33:N33) -> 1 | P33: 1 | Q33: 2 | S33: Dentro de una familia el cambio cuesta 0 y el orden interno es
E34: 8 | F34: 0 | G34: 0 | H34: 0 | I34: 0 | J34: 0 | K34: 0 | L34: 0 | M34: 1 | N34: 0 | O34: =SUM(F34:N34) -> 1 | P34: 1 | Q34: 1 | S34: irrelevante. Optimizar sobre bloques es exacto y baja el espacio
E35: Σ col | F35: =SUM(F26:F34) -> 1 | G35: =SUM(G26:G34) -> 1 | H35: =SUM(H26:H34) -> 1 | I35: =SUM(I26:I34) -> 1 | J35: =SUM(J26:J34) -> 1 | K35: =SUM(K26:K34) -> 1 | L35: =SUM(L26:L34) -> 1 | M35: =SUM(M26:M34) -> 1 | N35: =SUM(N26:N34) -> 1 | S35: de búsqueda de 17! ≈ 3,6×10¹⁴ a 8! = 40.320. Además cabe en el
E36: = | F36: 1 | G36: 1 | H36: 1 | I36: 1 | J36: 1 | K36: 1 | L36: 1 | M36: 1 | N36: 1 | S36: límite de 200 variables del Solver estándar de Excel.
A39: RESTRICCIÓN (4) MTZ: u(i) − u(j) + 9·x(i,j) debe ser ≤ 8
E40: i \ j | F40: 1 | G40: 2 | H40: 3 | I40: 4 | J40: 5 | K40: 6 | L40: 7 | M40: 8
E41: 1 | F41: 0 | G41: =$Q$27-$Q$28+9*H27 -> 2 | H41: =$Q$27-$Q$29+9*I27 -> 1 | I41: =$Q$27-$Q$30+9*J27 -> 3 | J41: =$Q$27-$Q$31+9*K27 -> 4 | K41: =$Q$27-$Q$32+9*L27 -> 5 | L41: =$Q$27-$Q$33+9*M27 -> 6 | M41: =$Q$27-$Q$34+9*N27 -> 7
E42: 2 | F42: =$Q$28-$Q$27+9*G28 -> -2 | G42: 0 | H42: =$Q$28-$Q$29+9*I28 -> 8 | I42: =$Q$28-$Q$30+9*J28 -> 1 | J42: =$Q$28-$Q$31+9*K28 -> 2 | K42: =$Q$28-$Q$32+9*L28 -> 3 | L42: =$Q$28-$Q$33+9*M28 -> 4 | M42: =$Q$28-$Q$34+9*N28 -> 5
E43: 3 | F43: =$Q$29-$Q$27+9*G29 -> 8 | G43: =$Q$29-$Q$28+9*H29 -> 1 | H43: 0 | I43: =$Q$29-$Q$30+9*J29 -> 2 | J43: =$Q$29-$Q$31+9*K29 -> 3 | K43: =$Q$29-$Q$32+9*L29 -> 4 | L43: =$Q$29-$Q$33+9*M29 -> 5 | M43: =$Q$29-$Q$34+9*N29 -> 6
...

Sheet 06_Secuencia_Optima
A1: SECUENCIA ÓPTIMA Y PRUEBA DE OPTIMALIDAD
A2: Ruta reconstruida desde variables de Solver. Las fórmulas recalculan el programa, pero no ejecutan automáticamente la optimización.
A4: PRUEBA DE OPTIMALIDAD DEL CASO BASE
A5: Vía 1 — Cota inferior combinatoria (se demuestra sin computador) | E5: Los cambios de 0 minutos parten los 17 productos en 8 bloques disjuntos, y no existe ningún cambio de 0 minutos entre bloques distintos. Por lo tanto CUALQUIER secuencia de los 17 productos cruza al menos 7 veces de un bloque a otro, y cada uno de esos cruces cuesta como mínimo 120 minutos. Luego ninguna secuencia puede costar menos de 7 × 120 = 840 minutos.
A6: Verificación de la secuencia | E6: La ruta expandida visita una vez cada producto y suma 840 minutos en la matriz original. Al alcanzar la cota inferior, prueba la optimalidad de cambios del caso base. No se adjunta una ejecución independiente de Held-Karp.
A7: Conclusión | E7: La secuencia base alcanza 840 minutos con siete cambios de 120. La matriz contiene 30 transiciones de 180 minutos (15 pares). La optimalidad se refiere al tiempo de cambio, no a costos o fechas de entrega.
A9: Cota inferior (7 cruces × 120 min) | D9: ='05_Modelo_Solver'!C7 -> 840 | E9: Solución | F9: =SUM($F$26:$F$42) -> 840 | G9: =IF(AND(F9=D9,'10_KPIs'!C23="OK (17/17)",'10_KPIs'!C28="OK"),"ÓPTIMO DEMOSTRADO","No demostrado") -> ÓPTIMO DEMOSTRADO
A13: RUTA ÓPTIMA DE BLOQUES (leída desde las variables u(i) del Solver) | E13: La ruta se lee de las posiciones u(i) de Solver. Después de cambiar la matriz, ejecutar Solver y verificar la ruta a nivel de producto.
A14: Posición | B14: Nodo | C14: Rep. Id | D14: Familia | E14: Cambio (min)
A15: 1 | B15: =INDEX('05_Modelo_Solver'!$A$12:$A$19,MATCH($A15,'05_Modelo_Solver'!$Q$27:$Q$34,0)) -> 8 | C15: =INDEX('05_Modelo_Solver'!$C$12:$C$19,MATCH($B15,'05_Modelo_Solver'!$A$12:$A$19,0)) -> 3533 | D15: =INDEX('05_Modelo_Solver'!$B$12:$B$19,MATCH($B15,'05_Modelo_Solver'!$A$12:$A$19,0)) -> S5 Vinagre | E15: =IF($A15=1,0,INDEX('05_Modelo_Solver'!$F$11:$N$19,$B14+1,$B15+1)) -> 0
A16: 2 | B16: =INDEX('05_Modelo_Solver'!$A$12:$A$19,MATCH($A16,'05_Modelo_Solver'!$Q$27:$Q$34,0)) -> 7 | C16: =INDEX('05_Modelo_Solver'!$C$12:$C$19,MATCH($B16,'05_Modelo_Solver'!$A$12:$A$19,0)) -> 3643 | D16: =INDEX('05_Modelo_Solver'!$B$12:$B$19,MATCH($B16,'05_Modelo_Solver'!$A$12:$A$19,0)) -> S4 Rosada | E16: =IF($A16=1,0,INDEX('05_Modelo_Solver'!$F$11:$N$19,$B15+1,$B16+1)) -> 120
A17: 3 | B17: =INDEX('05_Modelo_Solver'!$A$12:$A$19,MATCH($A17,'05_Modelo_Solver'!$Q$27:$Q$34,0)) -> 6 | C17: =INDEX('05_Modelo_Solver'!$C$12:$C$19,MATCH($B17,'05_Modelo_Solver'!$A$12:$A$19,0)) -> 15564 | D17: =INDEX('05_Modelo_Solver'!$B$12:$B$19,MATCH($B17,'05_Modelo_Solver'!$A$12:$A$19,0)) -> S3 Napolitana | E17: =IF($A17=1,0,INDEX('05_Modelo_Solver'!$F$11:$N$19,$B16+1,$B17+1)) -> 120
A18: 4 | B18: =INDEX('05_Modelo_Solver'!$A$12:$A$19,MATCH($A18,'05_Modelo_Solver'!$Q$27:$Q$34,0)) -> 5 | C18: =INDEX('05_Modelo_Solver'!$C$12:$C$19,MATCH($B18,'05_Modelo_Solver'!$A$12:$A$19,0)) -> 5998 | D18: =INDEX('05_Modelo_Solver'!$B$12:$B$19,MATCH($B18,'05_Modelo_Solver'!$A$12:$A$19,0)) -> F3 Tomate | E18: =IF($A18=1,0,INDEX('05_Modelo_Solver'!$F$11:$N$19,$B17+1,$B18+1)) -> 120
A19: 5 | B19: =INDEX('05_Modelo_Solver'!$A$12:$A$19,MATCH($A19,'05_Modelo_Solver'!$Q$27:$Q$34,0)) -> 4 | C19: =INDEX('05_Modelo_Solver'!$C$12:$C$19,MATCH($B19,'05_Modelo_Solver'!$A$12:$A$19,0)) -> 6743 | D19: =INDEX('05_Modelo_Solver'!$B$12:$B$19,MATCH($B19,'05_Modelo_Solver'!$A$12:$A$19,0)) -> S2 Piña | E19: =IF($A19=1,0,INDEX('05_Modelo_Solver'!$F$11:$N$19,$B18+1,$B19+1)) -> 120
A20: 6 | B20: =INDEX('05_Modelo_Solver'!$A$12:$A$19,MATCH($A20,'05_Modelo_Solver'!$Q$27:$Q$34,0)) -> 2 | C20: =INDEX('05_Modelo_Solver'!$C$12:$C$19,MATCH($B20,'05_Modelo_Solver'!$A$12:$A$19,0)) -> 6639 | D20: =INDEX('05_Modelo_Solver'!$B$12:$B$19,MATCH($B20,'05_Modelo_Solver'!$A$12:$A$19,0)) -> S1 Barbecue | E20: =IF($A20=1,0,INDEX('05_Modelo_Solver'!$F$11:$N$19,$B19+1,$B20+1)) -> 120
A21: 7 | B21: =INDEX('05_Modelo_Solver'!$A$12:$A$19,MATCH($A21,'05_Modelo_Solver'!$Q$27:$Q$34,0)) -> 3 | C21: =INDEX('05_Modelo_Solver'!$C$12:$C$19,MATCH($B21,'05_Modelo_Solver'!$A$12:$A$19,0)) -> 3278 | D21: =INDEX('05_Modelo_Solver'!$B$12:$B$19,MATCH($B21,'05_Modelo_Solver'!$A$12:$A$19,0)) -> F2 Emulsiones | E21: =IF($A21=1,0,INDEX('05_Modelo_Solver'!$F$11:$N$19,$B20+1,$B21+1)) -> 120
A22: 8 | B22: =INDEX('05_Modelo_Solver'!$A$12:$A$19,MATCH($A22,'05_Modelo_Solver'!$Q$27:$Q$34,0)) -> 1 | C22: =INDEX('05_Modelo_Solver'!$C$12:$C$19,MATCH($B22,'05_Modelo_Solver'!$A$12:$A$19,0)) -> 3757 | D22: =INDEX('05_Modelo_Solver'!$B$12:$B$19,MATCH($B22,'05_Modelo_Solver'!$A$12:$A$19,0)) -> F1 Mostazas | E22: =IF($A22=1,0,INDEX('05_Modelo_Solver'!$F$11:$N$19,$B21+1,$B22+1)) -> 120
A23: MOTOR DE CÁLCULO DEL PLAN — línea de tiempo continua en minutos desde el arranque del mes | E23: El fin de cada referencia incluye la pequeña espera necesaria para no dividir cartones entre turnos. El tiempo productivo neto sigue siendo necesidad × minutos/cartón.
T24: AUXILIAR — reconstrucción del orden
A25: Orden | B25: Id | C25: Descripción | D25: Bloque | E25: Producto anterior | F25: Tiempo cambio (min) | G25: Necesidad (cartones) | H25: Cartones /Turno | I25: Min /Cartón | J25: Minutos producción | K25: Inicio cambio | L25: Inicio producción | M25: Fin producción | N25: Turno inicio | O25: Turno fin | P25: Fecha inicio | Q25: Fecha fin | T25: Id | U25: Bloque | V25: Pos.blq | W25: Rank int. | X25: Clave | Y25: Orden | Z25: Min hasta cierre del primer turno | AA25: Cartones que caben en primer turno | AB25: Espera por cartón completo (min)
A26: 1 | B26: =INDEX($T$26:$T$42,MATCH($A26,$Y$26:$Y$42,0)) -> 3533 | C26: =INDEX('02_Datos_Maestros'!$B$5:$B$21,MATCH($B26,'02_Datos_Maestros'!$A$5:$A$21,0)) -> VINAGRE BLANCO (24DP/1/230ml) | D26: =INDEX('02_Datos_Maestros'!$I$5:$I$21,MATCH($B26,'02_Datos_Maestros'!$A$5:$A$21,0)) -> 3533 | E26: =IF($A26=1,"—",$B25) -> — | F26: =IF($A26=1,0,INDEX('04_Matriz_Cambios'!$B$6:$R$22,MATCH($E26,'04_Matriz_Cambios'!$A$6:$A$22,0),MATCH($B26,'04_Matriz_Cambios'!$B$5:$R$5,0))) -> 0 | G26: =INDEX('03_Demanda_ABC'!$C$5:$C$21,MATCH($B26,'03_Demanda_ABC'!$A$5:$A$21,0)) -> 3834 | H26: =INDEX('02_Datos_Maestros'!$F$5:$F$21,MATCH($B26,'02_Datos_Maestros'!$A$5:$A$21,0)) -> 1123 | I26: =480/$H26 -> 0.42742654 | J26: =$G26*$I26 -> 1638.7533 | K26: =0 -> 0 | L26: =SUM(K26,F26) -> 0 | M26: =L26+J26+AB26 -> 1638.7533 | N26: =INT($L26/480)+1 -> 1 | O26: =INT(($M26-0.0001)/480)+1 -> 4 | P26: =IF(N26>MAX('07_Calendario'!$F$5:$F$82),"Fuera del mes",INDEX('07_Calendario'!$B$5:$B$82,MATCH(N26,'07_Calendario'!$F$5:$F$82,0))) -> 46266 | Q26: =IF(O26>MAX('07_Calendario'!$F$5:$F$82),"Fuera del mes",INDEX('07_Calendario'!$B$5:$B$82,MATCH(O26,'07_Calendario'!$F$5:$F$82,0))) -> 46267 | T26: ='02_Datos_Maestros'!$A$5 -> 3278 | U26: ='02_Datos_Maestros'!$I$5 -> 3278 | V26: =MATCH($U26,$C$15:$C$22,0) -> 7 | W26: =COUNTIFS($U$26:$U$42,$U26,$T$26:$T$42,"<="&$T26) -> 1 | X26: =$V26*100+$W26 -> 701 | Y26: =RANK($X26,$X$26:$X$42,1) -> 9 | Z26: =480-MOD(L26,480) -> 480 | AA26: =INT(ROUND(Z26*H26/480,6)) -> 1123 | AB26: =IF(G26>AA26,MAX(0,Z26-AA26*I26),0) -> 0
A27: 2 | B27: =INDEX($T$26:$T$42,MATCH($A27,$Y$26:$Y$42,0)) -> 3643 | C27: =INDEX('02_Datos_Maestros'!$B$5:$B$21,MATCH($B27,'02_Datos_Maestros'!$A$5:$A$21,0)) -> SALSA ROSADA (12DP/1/380g) | D27: =INDEX('02_Datos_Maestros'!$I$5:$I$21,MATCH($B27,'02_Datos_Maestros'!$A$5:$A$21,0)) -> 3643 | E27: =IF($A27=1,"—",$B26) -> 3533 | F27: =IF($A27=1,0,INDEX('04_Matriz_Cambios'!$B$6:$R$22,MATCH($E27,'04_Matriz_Cambios'!$A$6:$A$22,0),MATCH($B27,'04_Matriz_Cambios'!$B$5:$R$5,0))) -> 120 | G27: =INDEX('03_Demanda_ABC'!$C$5:$C$21,MATCH($B27,'03_Demanda_ABC'!$A$5:$A$21,0)) -> 3220 | H27: =INDEX('02_Datos_Maestros'!$F$5:$F$21,MATCH($B27,'02_Datos_Maestros'!$A$5:$A$21,0)) -> 2460 | I27: =480/$H27 -> 0.19512195 | J27: =$G27*$I27 -> 628.29268 | K27: =0 -> 0 | L27: =SUM(K27,F27) -> 120 | M27: =L27+J27+AB27 -> 748.29268 | N27: =INT($L27/480)+1 -> 1 | O27: =INT(($M27-0.0001)/480)+1 -> 2 | P27: =IF(N27>MAX('07_Calendario'!$F$5:$F$82),"Fuera del mes",INDEX('07_Calendario'!$B$5:$B$82,MATCH(N27,'07_Calendario'!$F$5:$F$82,0))) -> 46266 | Q27: =IF(O27>MAX('07_Calendario'!$F$5:$F$82),"Fuera del mes",INDEX('07_Calendario'!$B$5:$B$82,MATCH(O27,'07_Calendario'!$F$5:$F$82,0))) -> 46266 | T27: ='02_Datos_Maestros'!$A$6 -> 3533 | U27: ='02_Datos_Maestros'!$I$6 -> 3533 | V27: =MATCH($U27,$C$15:$C$22,0) -> 1 | W27: =COUNTIFS($U$26:$U$42,$U27,$T$26:$T$42,"<="&$T27) -> 1 | X27: =$V27*100+$W27 -> 101 | Y27: =RANK($X27,$X$26:$X$42,1) -> 1 | Z27: =480-MOD(L27,480) -> 360 | AA27: =INT(ROUND(Z27*H27/480,6)) -> 1845 | AB27: =IF(G27>AA27,MAX(0,Z27-AA27*I27),0) -> 0
A28: 3 | B28: =INDEX($T$26:$T$42,MATCH($A28,$Y$26:$Y$42,0)) -> 15564 | C28: =INDEX('02_Datos_Maestros'!$B$5:$B$21,MATCH($B28,'02_Datos_Maestros'!$A$5:$A$21,0)) -> SALSA NAPOLITANA (24DP/1/200g) | D28: =INDEX('02_Datos_Maestros'!$I$5:$I$21,MATCH($B28,'02_Datos_Maestros'!$A$5:$A$21,0)) -> 15564 | E28: =IF($A28=1,"—",$B27) -> 3643 | F28: =IF($A28=1,0,INDEX('04_Matriz_Cambios'!$B$6:$R$22,MATCH($E28,'04_Matriz_Cambios'!$A$6:$A$22,0),MATCH($B28,'04_Matriz_Cambios'!$B$5:$R$5,0))) -> 120 | G28: =INDEX('03_Demanda_ABC'!$C$5:$C$21,MATCH($B28,'03_Demanda_ABC'!$A$5:$A$21,0)) -> 1840 | H28: =INDEX('02_Datos_Maestros'!$F$5:$F$21,MATCH($B28,'02_Datos_Maestros'!$A$5:$A$21,0)) -> 1684 | I28: =480/$H28 -> 0.28503563 | J28: =$G28*$I28 -> 524.46556 | K28: =0 -> 0 | L28: =SUM(K28,F28) -> 120 | M28: =L28+J28+AB28 -> 644.46556 | N28: =INT($L28/480)+1 -> 1 | O28: =INT(($M28-0.0001)/480)+1 -> 2 | P28: =IF(N28>MAX('07_Calendario'!$F$5:$F$82),"Fuera del mes",INDEX('07_Calendario'!$B$5:$B$82,MATCH(N28,'07_Calendario'!$F$5:$F$82,0))) -> 46266 | Q28: =IF(O28>MAX('07_Calendario'!$F$5:$F$82),"Fuera del mes",INDEX('07_Calendario'!$B$5:$B$82,MATCH(O28,'07_Calendario'!$F$5:$F$82,0))) -> 46266 | T28: ='02_Datos_Maestros'!$A$7 -> 3643 | U28: ='02_Datos_Maestros'!$I$7 -> 3643 | V28: =MATCH($U28,$C$15:$C$22,0) -> 2 | W28: =COUNTIFS($U$26:$U$42,$U28,$T$26:$T$42,"<="&$T28) -> 1 | X28: =$V28*100+$W28 -> 201 | Y28: =RANK($X28,$X$26:$X$42,1) -> 2 | Z28: =480-MOD(L28,480) -> 360 | AA28: =INT(ROUND(Z28*H28/480,6)) -> 1263 | AB28: =IF(G28>AA28,MAX(0,Z28-AA28*I28),0) -> 0
A29: 4 | B29: =INDEX($T$26:$T$42,MATCH($A29,$Y$26:$Y$42,0)) -> 5998 | C29: =INDEX('02_Datos_Maestros'!$B$5:$B$21,MATCH($B29,'02_Datos_Maestros'!$A$5:$A$21,0)) -> SALSA DE TOMATE ZEV (20DP/1/500g) | D29: =INDEX('02_Datos_Maestros'!$I$5:$I$21,MATCH($B29,'02_Datos_Maestros'!$A$5:$A$21,0)) -> 5998 | E29: =IF($A29=1,"—",$B28) -> 15564 | F29: =IF($A29=1,0,INDEX('04_Matriz_Cambios'!$B$6:$R$22,MATCH($E29,'04_Matriz_Cambios'!$A$6:$A$22,0),MATCH($B29,'04_Matriz_Cambios'!$B$5:$R$5,0))) -> 120 | G29: =INDEX('03_Demanda_ABC'!$C$5:$C$21,MATCH($B29,'03_Demanda_ABC'!$A$5:$A$21,0)) -> 20286 | H29: =INDEX('02_Datos_Maestros'!$F$5:$F$21,MATCH($B29,'02_Datos_Maestros'!$A$5:$A$21,0)) -> 1476 | I29: =480/$H29 -> 0.32520325 | J29: =$G29*$I29 -> 6597.0732 | K29: =0 -> 0 | L29: =SUM(K29,F29) -> 120 | M29: =L29+J29+AB29 -> 6717.0732 | N29: =INT($L29/480)+1 -> 1 | O29: =INT(($M29-0.0001)/480)+1 -> 14 | P29: =IF(N29>MAX('07_Calendario'!$F$5:$F$82),"Fuera del mes",INDEX('07_Calendario'!$B$5:$B$82,MATCH(N29,'07_Calendario'!$F$5:$F$82,0))) -> 46266 | Q29: =IF(O29>MAX('07_Calendario'!$F$5:$F$82),"Fuera del mes",INDEX('07_Calendario'!$B$5:$B$82,MATCH(O29,'07_Calendario'!$F$5:$F$82,0))) -> 46270 | T29: ='02_Datos_Maestros'!$A$8 -> 3749 | U29: ='02_Datos_Maestros'!$I$8 -> 3278 | V29: =MATCH($U29,$C$15:$C$22,0) -> 7 | W29: =COUNTIFS($U$26:$U$42,$U29,$T$26:$T$42,"<="&$T29) -> 2 | X29: =$V29*100+$W29 -> 702 | Y29: =RANK($X29,$X$26:$X$42,1) -> 10 | Z29: =480-MOD(L29,480) -> 360 | AA29: =INT(ROUND(Z29*H29/480,6)) -> 1107 | AB29: =IF(G29>AA29,MAX(0,Z29-AA29*I29),0) -> 0
A30: 5 | B30: =INDEX($T$26:$T$42,MATCH($A30,$Y$26:$Y$42,0)) -> 15881 | C30: =INDEX('02_Datos_Maestros'!$B$5:$B$21,MATCH($B30,'02_Datos_Maestros'!$A$5:$A$21,0)) -> SALSA DE TOMATE SAVORIA (12DP/1/500g) | D30: =INDEX('02_Datos_Maestros'!$I$5:$I$21,MATCH($B30,'02_Datos_Maestros'!$A$5:$A$21,0)) -> 5998 | E30: =IF($A30=1,"—",$B29) -> 5998 | F30: =IF($A30=1,0,INDEX('04_Matriz_Cambios'!$B$6:$R$22,MATCH($E30,'04_Matriz_Cambios'!$A$6:$A$22,0),MATCH($B30,'04_Matriz_Cambios'!$B$5:$R$5,0))) -> 0 | G30: =INDEX('03_Demanda_ABC'!$C$5:$C$21,MATCH($B30,'03_Demanda_ABC'!$A$5:$A$21,0)) -> 3540 | H30: =INDEX('02_Datos_Maestros'!$F$5:$F$21,MATCH($B30,'02_Datos_Maestros'!$A$5:$A$21,0)) -> 1476 | I30: =480/$H30 -> 0.32520325 | J30: =$G30*$I30 -> 1151.2195 | K30: =0 -> 0 | L30: =SUM(K30,F30) -> 0 | M30: =L30+J30+AB30 -> 1151.2195 | N30: =INT($L30/480)+1 -> 1 | O30: =INT(($M30-0.0001)/480)+1 -> 3 | P30: =IF(N30>MAX('07_Calendario'!$F$5:$F$82),"Fuera del mes",INDEX('07_Calendario'!$B$5:$B$82,MATCH(N30,'07_Calendario'!$F$5:$F$82,0))) -> 46266 | Q30: =IF(O30>MAX('07_Calendario'!$F$5:$F$82),"Fuera del mes",INDEX('07_Calendario'!$B$5:$B$82,MATCH(O30,'07_Calendario'!$F$5:$F$82,0))) -> 46266 | T30: ='02_Datos_Maestros'!$A$9 -> 3757 | U30: ='02_Datos_Maestros'!$I$9 -> 3757 | V30: =MATCH($U30,$C$15:$C$22,0) -> 8 | W30: =COUNTIFS($U$26:$U$42,$U30,$T$26:$T$42,"<="&$T30) -> 1 | X30: =$V30*100+$W30 -> 801 | Y30: =RANK($X30,$X$26:$X$42,1) -> 15 | Z30: =480-MOD(L30,480) -> 480 | AA30: =INT(ROUND(Z30*H30/480,6)) -> 1476 | AB30: =IF(G30>AA30,MAX(0,Z30-AA30*I30),0) -> 0
A31: 6 | B31: =INDEX($T$26:$T$42,MATCH($A31,$Y$26:$Y$42,0)) -> 16787 | C31: =INDEX('02_Datos_Maestros'!$B$5:$B$21,MATCH($B31,'02_Datos_Maestros'!$A$5:$A$21,0)) -> SALSA DE TOMATE SAVORIA (12DP/1/1000g) | D31: =INDEX('02_Datos_Maestros'!$I$5:$I$21,MATCH($B31,'02_Datos_Maestros'!$A$5:$A$21,0)) -> 5998 | E31: =IF($A31=1,"—",$B30) -> 15881 | F31: =IF($A31=1,0,INDEX('04_Matriz_Cambios'!$B$6:$R$22,MATCH($E31,'04_Matriz_Cambios'!$A$6:$A$22,0),MATCH($B31,'04_Matriz_Cambios'!$B$5:$R$5,0))) -> 0 | G31: =INDEX('03_Demanda_ABC'!$C$5:$C$21,MATCH($B31,'03_Demanda_ABC'!$A$5:$A$21,0)) -> 1000 | H31: =INDEX('02_Datos_Maestros'!$F$5:$F$21,MATCH($B31,'02_Datos_Maestros'!$A$5:$A$21,0)) -> 1686 | I31: =480/$H31 -> 0.28469751 | J31: =$G31*$I31 -> 284.69751 | K31: =0 -> 0 | L31: =SUM(K31,F31) -> 0 | M31: =L31+J31+AB31 -> 284.69751 | N31: =INT($L31/480)+1 -> 1 | O31: =INT(($M31-0.0001)/480)+1 -> 1 | P31: =IF(N31>MAX('07_Calendario'!$F$5:$F$82),"Fuera del mes",INDEX('07_Calendario'!$B$5:$B$82,MATCH(N31,'07_Calendario'!$F$5:$F$82,0))) -> 46266 | Q31: =IF(O31>MAX('07_Calendario'!$F$5:$F$82),"Fuera del mes",INDEX('07_Calendario'!$B$5:$B$82,MATCH(O31,'07_Calendario'!$F$5:$F$82,0))) -> 46266 | T31: ='02_Datos_Maestros'!$A$10 -> 3925 | U31: ='02_Datos_Maestros'!$I$10 -> 3757 | V31: =MATCH($U31,$C$15:$C$22,0) -> 8 | W31: =COUNTIFS($U$26:$U$42,$U31,$T$26:$T$42,"<="&$T31) -> 2 | X31: =$V31*100+$W31 -> 802 | Y31: =RANK($X31,$X$26:$X$42,1) -> 16 | Z31: =480-MOD(L31,480) -> 480 | AA31: =INT(ROUND(Z31*H31/480,6)) -> 1686 | AB31: =IF(G31>AA31,MAX(0,Z31-AA31*I31),0) -> 0
A32: 7 | B32: =INDEX($T$26:$T$42,MATCH($A32,$Y$26:$Y$42,0)) -> 6743 | C32: =INDEX('02_Datos_Maestros'!$B$5:$B$21,MATCH($B32,'02_Datos_Maestros'!$A$5:$A$21,0)) -> SALSA DE PIÑA (12DP/1/400g) | D32: =INDEX('02_Datos_Maestros'!$I$5:$I$21,MATCH($B32,'02_Datos_Maestros'!$A$5:$A$21,0)) -> 6743 | E32: =IF($A32=1,"—",$B31) -> 16787 | F32: =IF($A32=1,0,INDEX('04_Matriz_Cambios'!$B$6:$R$22,MATCH($E32,'04_Matriz_Cambios'!$A$6:$A$22,0),MATCH($B32,'04_Matriz_Cambios'!$B$5:$R$5,0))) -> 120 | G32: =INDEX('03_Demanda_ABC'!$C$5:$C$21,MATCH($B32,'03_Demanda_ABC'!$A$5:$A$21,0)) -> 2754 | H32: =INDEX('02_Datos_Maestros'!$F$5:$F$21,MATCH($B32,'02_Datos_Maestros'!$A$5:$A$21,0)) -> 1502 | I32: =480/$H32 -> 0.3195739 | J32: =$G32*$I32 -> 880.10652 | K32: =0 -> 0 | L32: =SUM(K32,F32) -> 120 | M32: =L32+J32+AB32 -> 1000.2663 | N32: =INT($L32/480)+1 -> 1 | O32: =INT(($M32-0.0001)/480)+1 -> 3 | P32: =IF(N32>MAX('07_Calendario'!$F$5:$F$82),"Fuera del mes",INDEX('07_Calendario'!$B$5:$B$82,MATCH(N32,'07_Calendario'!$F$5:$F$82,0))) -> 46266 | Q32: =IF(O32>MAX('07_Calendario'!$F$5:$F$82),"Fuera del mes",INDEX('07_Calendario'!$B$5:$B$82,MATCH(O32,'07_Calendario'!$F$5:$F$82,0))) -> 46266 | T32: ='02_Datos_Maestros'!$A$11 -> 5998 | U32: ='02_Datos_Maestros'!$I$11 -> 5998 | V32: =MATCH($U32,$C$15:$C$22,0) -> 4 | W32: =COUNTIFS($U$26:$U$42,$U32,$T$26:$T$42,"<="&$T32) -> 1 | X32: =$V32*100+$W32 -> 401 | Y32: =RANK($X32,$X$26:$X$42,1) -> 4 | Z32: =480-MOD(L32,480) -> 360 | AA32: =INT(ROUND(Z32*H32/480,6)) -> 1126 | AB32: =IF(G32>AA32,MAX(0,Z32-AA32*I32),0) -> 0.15978695
A33: 8 | B33: =INDEX($T$26:$T$42,MATCH($A33,$Y$26:$Y$42,0)) -> 6639 | C33: =INDEX('02_Datos_Maestros'!$B$5:$B$21,MATCH($B33,'02_Datos_Maestros'!$A$5:$A$21,0)) -> SALSA BARBECUE (12DP/1/400g) | D33: =INDEX('02_Datos_Maestros'!$I$5:$I$21,MATCH($B33,'02_Datos_Maestros'!$A$5:$A$21,0)) -> 6639 | E33: =IF($A33=1,"—",$B32) -> 6743 | F33: =IF($A33=1,0,INDEX('04_Matriz_Cambios'!$B$6:$R$22,MATCH($E33,'04_Matriz_Cambios'!$A$6:$A$22,0),MATCH($B33,'04_Matriz_Cambios'!$B$5:$R$5,0))) -> 120 | G33: =INDEX('03_Demanda_ABC'!$C$5:$C$21,MATCH($B33,'03_Demanda_ABC'!$A$5:$A$21,0)) -> 2900 | H33: =INDEX('02_Datos_Maestros'!$F$5:$F$21,MATCH($B33,'02_Datos_Maestros'!$A$5:$A$21,0)) -> 2493 | I33: =480/$H33 -> 0.19253911 | J33: =$G33*$I33 -> 558.36342 | K33: =0 -> 0 | L33: =SUM(K33,F33) -> 120 | M33: =L33+J33+AB33 -> 678.50782 | N33: =INT($L33/480)+1 -> 1 | O33: =INT(($M33-0.0001)/480)+1 -> 2 | P33: =IF(N33>MAX('07_Calendario'!$F$5:$F$82),"Fuera del mes",INDEX('07_Calendario'!$B$5:$B$82,MATCH(N33,'07_Calendario'!$F$5:$F$82,0))) -> 46266 | Q33: =IF(O33>MAX('07_Calendario'!$F$5:$F$82),"Fuera del mes",INDEX('07_Calendario'!$B$5:$B$82,MATCH(O33,'07_Calendario'!$F$5:$F$82,0))) -> 46266 | T33: ='02_Datos_Maestros'!$A$12 -> 6616 | U33: ='02_Datos_Maestros'!$I$12 -> 3757 | V33: =MATCH($U33,$C$15:$C$22,0) -> 8 | W33: =COUNTIFS($U$26:$U$42,$U33,$T$26:$T$42,"<="&$T33) -> 3 | X33: =$V33*100+$W33 -> 803 | Y33: =RANK($X33,$X$26:$X$42,1) -> 17 | Z33: =480-MOD(L33,480) -> 360 | AA33: =INT(ROUND(Z33*H33/480,6)) -> 1869 | AB33: =IF(G33>AA33,MAX(0,Z33-AA33*I33),0) -> 0.14440433
A34: 9 | B34: =INDEX($T$26:$T$42,MATCH($A34,$Y$26:$Y$42,0)) -> 3278 | C34: =INDEX('02_Datos_Maestros'!$B$5:$B$21,MATCH($B34,'02_Datos_Maestros'!$A$5:$A$21,0)) -> SALSA MAYONESA (12DP/1/380g) | D34: =INDEX('02_Datos_Maestros'!$I$5:$I$21,MATCH($B34,'02_Datos_Maestros'!$A$5:$A$21,0)) -> 3278 | E34: =IF($A34=1,"—",$B33) -> 6639 | F34: =IF($A34=1,0,INDEX('04_Matriz_Cambios'!$B$6:$R$22,MATCH($E34,'04_Matriz_Cambios'!$A$6:$A$22,0),MATCH($B34,'04_Matriz_Cambios'!$B$5:$R$5,0))) -> 120 | G34: =INDEX('03_Demanda_ABC'!$C$5:$C$21,MATCH($B34,'03_Demanda_ABC'!$A$5:$A$21,0)) -> 6206 | H34: =INDEX('02_Datos_Maestros'!$F$5:$F$21,MATCH($B34,'02_Datos_Maestros'!$A$5:$A$21,0)) -> 2460 | I34: =480/$H34 -> 0.19512195 | J34: =$G34*$I34 -> 1210.9268 | K34: =0 -> 0 | L34: =SUM(K34,F34) -> 120 | M34: =L34+J34+AB34 -> 1330.9268 | N34: =INT($L34/480)+1 -> 1 | O34: =INT(($M34-0.0001)/480)+1 -> 3 | P34: =IF(N34>MAX('07_Calendario'!$F$5:$F$82),"Fuera del mes",INDEX('07_Calendario'!$B$5:$B$82,MATCH(N34,'07_Calendario'!$F$5:$F$82,0))) -> 46266 | Q34: =IF(O34>MAX('07_Calendario'!$F$5:$F$82),"Fuera del mes",INDEX('07_Calendario'!$B$5:$B$82,MATCH(O34,'07_Calendario'!$F$5:$F$82,0))) -> 46266 | T34: ='02_Datos_Maestros'!$A$13 -> 6639 | U34: ='02_Datos_Maestros'!$I$13 -> 6639 | V34: =MATCH($U34,$C$15:$C$22,0) -> 6 | W34: =COUNTIFS($U$26:$U$42,$U34,$T$26:$T$42,"<="&$T34) -> 1 | X34: =$V34*100+$W34 -> 601 | Y34: =RANK($X34,$X$26:$X$42,1) -> 8 | Z34: =480-MOD(L34,480) -> 360 | AA34: =INT(ROUND(Z34*H34/480,6)) -> 1845 | AB34: =IF(G34>AA34,MAX(0,Z34-AA34*I34),0) -> 0
A35: 10 | B35: =INDEX($T$26:$T$42,MATCH($A35,$Y$26:$Y$42,0)) -> 3749 | C35: =INDEX('02_Datos_Maestros'!$B$5:$B$21,MATCH($B35,'02_Datos_Maestros'!$A$5:$A$21,0)) -> SALSA MAYONESA (12DP/1/1000g) | D35: =INDEX('02_Datos_Maestros'!$I$5:$I$21,MATCH($B35,'02_Datos_Maestros'!$A$5:$A$21,0)) -> 3278 | E35: =IF($A35=1,"—",$B34) -> 3278 | F35: =IF($A35=1,0,INDEX('04_Matriz_Cambios'!$B$6:$R$22,MATCH($E35,'04_Matriz_Cambios'!$A$6:$A$22,0),MATCH($B35,'04_Matriz_Cambios'!$B$5:$R$5,0))) -> 0 | G35: =INDEX('03_Demanda_ABC'!$C$5:$C$21,MATCH($B35,'03_Demanda_ABC'!$A$5:$A$21,0)) -> 4440 | H35: =INDEX('02_Datos_Maestros'!$F$5:$F$21,MATCH($B35,'02_Datos_Maestros'!$A$5:$A$21,0)) -> 1352 | I35: =480/$H35 -> 0.35502959 | J35: =$G35*$I35 -> 1576.3314 | K35: =0 -> 0 | L35: =SUM(K35,F35) -> 0 | M35: =L35+J35+AB35 -> 1576.3314 | N35: =INT($L35/480)+1 -> 1 | O35: =INT(($M35-0.0001)/480)+1 -> 4 | P35: =IF(N35>MAX('07_Calendario'!$F$5:$F$82),"Fuera del mes",INDEX('07_Calendario'!$B$5:$B$82,MATCH(N35,'07_Calendario'!$F$5:$F$82,0))) -> 46266 | Q35: =IF(O35>MAX('07_Calendario'!$F$5:$F$82),"Fuera del mes",INDEX('07_Calendario'!$B$5:$B$82,MATCH(O35,'07_Calendario'!$F$5:$F$82,0))) -> 46267 | T35: ='02_Datos_Maestros'!$A$14 -> 6743 | U35: ='02_Datos_Maestros'!$I$14 -> 6743 | V35: =MATCH($U35,$C$15:$C$22,0) -> 5 | W35: =COUNTIFS($U$26:$U$42,$U35,$T$26:$T$42,"<="&$T35) -> 1 | X35: =$V35*100+$W35 -> 501 | Y35: =RANK($X35,$X$26:$X$42,1) -> 7 | Z35: =480-MOD(L35,480) -> 480 | AA35: =INT(ROUND(Z35*H35/480,6)) -> 1352 | AB35: =IF(G35>AA35,MAX(0,Z35-AA35*I35),0) -> 0
A36: 11 | B36: =INDEX($T$26:$T$42,MATCH($A36,$Y$26:$Y$42,0)) -> 7590 | C36: =INDEX('02_Datos_Maestros'!$B$5:$B$21,MATCH($B36,'02_Datos_Maestros'!$A$5:$A$21,0)) -> SALSA MAYONESA (12DP/1/600g) | D36: =INDEX('02_Datos_Maestros'!$I$5:$I$21,MATCH($B36,'02_Datos_Maestros'!$A$5:$A$21,0)) -> 3278 | E36: =IF($A36=1,"—",$B35) -> 3749 | F36: =IF($A36=1,0,INDEX('04_Matriz_Cambios'!$B$6:$R$22,MATCH($E36,'04_Matriz_Cambios'!$A$6:$A$22,0),MATCH($B36,'04_Matriz_Cambios'!$B$5:$R$5,0))) -> 0 | G36: =INDEX('03_Demanda_ABC'!$C$5:$C$21,MATCH($B36,'03_Demanda_ABC'!$A$5:$A$21,0)) -> 1496 | H36: =INDEX('02_Datos_Maestros'!$F$5:$F$21,MATCH($B36,'02_Datos_Maestros'!$A$5:$A$21,0)) -> 2001 | I36: =480/$H36 -> 0.23988006 | J36: =$G36*$I36 -> 358.86057 | K36: =0 -> 0 | L36: =SUM(K36,F36) -> 0 | M36: =L36+J36+AB36 -> 358.86057 | N36: =INT($L36/480)+1 -> 1 | O36: =INT(($M36-0.0001)/480)+1 -> 1 | P36: =IF(N36>MAX('07_Calendario'!$F$5:$F$82),"Fuera del mes",INDEX('07_Calendario'!$B$5:$B$82,MATCH(N36,'07_Calendario'!$F$5:$F$82,0))) -> 46266 | Q36: =IF(O36>MAX('07_Calendario'!$F$5:$F$82),"Fuera del mes",INDEX('07_Calendario'!$B$5:$B$82,MATCH(O36,'07_Calendario'!$F$5:$F$82,0))) -> 46266 | T36: ='02_Datos_Maestros'!$A$15 -> 7590 | U36: ='02_Datos_Maestros'!$I$15 -> 3278 | V36: =MATCH($U36,$C$15:$C$22,0) -> 7 | W36: =COUNTIFS($U$26:$U$42,$U36,$T$26:$T$42,"<="&$T36) -> 3 | X36: =$V36*100+$W36 -> 703 | Y36: =RANK($X36,$X$26:$X$42,1) -> 11 | Z36: =480-MOD(L36,480) -> 480 | AA36: =INT(ROUND(Z36*H36/480,6)) -> 2001 | AB36: =IF(G36>AA36,MAX(0,Z36-AA36*I36),0) -> 0
A37: 12 | B37: =INDEX($T$26:$T$42,MATCH($A37,$Y$26:$Y$42,0)) -> 15795 | C37: =INDEX('02_Datos_Maestros'!$B$5:$B$21,MATCH($B37,'02_Datos_Maestros'!$A$5:$A$21,0)) -> SALSA MAYONESA-V(12DP/1/380g) | D37: =INDEX('02_Datos_Maestros'!$I$5:$I$21,MATCH($B37,'02_Datos_Maestros'!$A$5:$A$21,0)) -> 3278 | E37: =IF($A37=1,"—",$B36) -> 7590 | F37: =IF($A37=1,0,INDEX('04_Matriz_Cambios'!$B$6:$R$22,MATCH($E37,'04_Matriz_Cambios'!$A$6:$A$22,0),MATCH($B37,'04_Matriz_Cambios'!$B$5:$R$5,0))) -> 0 | G37: =INDEX('03_Demanda_ABC'!$C$5:$C$21,MATCH($B37,'03_Demanda_ABC'!$A$5:$A$21,0)) -> 1284 | H37: =INDEX('02_Datos_Maestros'!$F$5:$F$21,MATCH($B37,'02_Datos_Maestros'!$A$5:$A$21,0)) -> 2001 | I37: =480/$H37 -> 0.23988006 | J37: =$G37*$I37 -> 308.006 | K37: =0 -> 0 | L37: =SUM(K37,F37) -> 0 | M37: =L37+J37+AB37 -> 308.006 | N37: =INT($L37/480)+1 -> 1 | O37: =INT(($M37-0.0001)/480)+1 -> 1 | P37: =IF(N37>MAX('07_Calendario'!$F$5:$F$82),"Fuera del mes",INDEX('07_Calendario'!$B$5:$B$82,MATCH(N37,'07_Calendario'!$F$5:$F$82,0))) -> 46266 | Q37: =IF(O37>MAX('07_Calendario'!$F$5:$F$82),"Fuera del mes",INDEX('07_Calendario'!$B$5:$B$82,MATCH(O37,'07_Calendario'!$F$5:$F$82,0))) -> 46266 | T37: ='02_Datos_Maestros'!$A$16 -> 15564 | U37: ='02_Datos_Maestros'!$I$16 -> 15564 | V37: =MATCH($U37,$C$15:$C$22,0) -> 3 | W37: =COUNTIFS($U$26:$U$42,$U37,$T$26:$T$42,"<="&$T37) -> 1 | X37: =$V37*100+$W37 -> 301 | Y37: =RANK($X37,$X$26:$X$42,1) -> 3 | Z37: =480-MOD(L37,480) -> 480 | AA37: =INT(ROUND(Z37*H37/480,6)) -> 2001 | AB37: =IF(G37>AA37,MAX(0,Z37-AA37*I37),0) -> 0
A38: 13 | B38: =INDEX($T$26:$T$42,MATCH($A38,$Y$26:$Y$42,0)) -> 16816 | C38: =INDEX('02_Datos_Maestros'!$B$5:$B$21,MATCH($B38,'02_Datos_Maestros'!$A$5:$A$21,0)) -> SALSA DE MAYONESA ZEV (24DP/1/400G) | D38: =INDEX('02_Datos_Maestros'!$I$5:$I$21,MATCH($B38,'02_Datos_Maestros'!$A$5:$A$21,0)) -> 3278 | E38: =IF($A38=1,"—",$B37) -> 15795 | F38: =IF($A38=1,0,INDEX('04_Matriz_Cambios'!$B$6:$R$22,MATCH($E38,'04_Matriz_Cambios'!$A$6:$A$22,0),MATCH($B38,'04_Matriz_Cambios'!$B$5:$R$5,0))) -> 0 | G38: =INDEX('03_Demanda_ABC'!$C$5:$C$21,MATCH($B38,'03_Demanda_ABC'!$A$5:$A$21,0)) -> 19200 | H38: =INDEX('02_Datos_Maestros'!$F$5:$F$21,MATCH($B38,'02_Datos_Maestros'!$A$5:$A$21,0)) -> 1200 | I38: =480/$H38 -> 0.4 | J38: =$G38*$I38 -> 7680 | K38: =0 -> 0 | L38: =SUM(K38,F38) -> 0 | M38: =L38+J38+AB38 -> 7680 | N38: =INT($L38/480)+1 -> 1 | O38: =INT(($M38-0.0001)/480)+1 -> 16 | P38: =IF(N38>MAX('07_Calendario'!$F$5:$F$82),"Fuera del mes",INDEX('07_Calendario'!$B$5:$B$82,MATCH(N38,'07_Calendario'!$F$5:$F$82,0))) -> 46266 | Q38: =IF(O38>MAX('07_Calendario'!$F$5:$F$82),"Fuera del mes",INDEX('07_Calendario'!$B$5:$B$82,MATCH(O38,'07_Calendario'!$F$5:$F$82,0))) -> 46272 | T38: ='02_Datos_Maestros'!$A$17 -> 15795 | U38: ='02_Datos_Maestros'!$I$17 -> 3278 | V38: =MATCH($U38,$C$15:$C$22,0) -> 7 | W38: =COUNTIFS($U$26:$U$42,$U38,$T$26:$T$42,"<="&$T38) -> 4 | X38: =$V38*100+$W38 -> 704 | Y38: =RANK($X38,$X$26:$X$42,1) -> 12 | Z38: =480-MOD(L38,480) -> 480 | AA38: =INT(ROUND(Z38*H38/480,6)) -> 1200 | AB38: =IF(G38>AA38,MAX(0,Z38-AA38*I38),0) -> 0
A39: 14 | B39: =INDEX($T$26:$T$42,MATCH($A39,$Y$26:$Y$42,0)) -> 17246 | C39: =INDEX('02_Datos_Maestros'!$B$5:$B$21,MATCH($B39,'02_Datos_Maestros'!$A$5:$A$21,0)) -> SALSA DE MAYONESA LINE (21DP/1/500G) | D39: =INDEX('02_Datos_Maestros'!$I$5:$I$21,MATCH($B39,'02_Datos_Maestros'!$A$5:$A$21,0)) -> 3278 | E39: =IF($A39=1,"—",$B38) -> 16816 | F39: =IF($A39=1,0,INDEX('04_Matriz_Cambios'!$B$6:$R$22,MATCH($E39,'04_Matriz_Cambios'!$A$6:$A$22,0),MATCH($B39,'04_Matriz_Cambios'!$B$5:$R$5,0))) -> 0 | G39: =INDEX('03_Demanda_ABC'!$C$5:$C$21,MATCH($B39,'03_Demanda_ABC'!$A$5:$A$21,0)) -> 7200 | H39: =INDEX('02_Datos_Maestros'!$F$5:$F$21,MATCH($B39,'02_Datos_Maestros'!$A$5:$A$21,0)) -> 1144 | I39: =480/$H39 -> 0.41958042 | J39: =$G39*$I39 -> 3020.979 | K39: =0 -> 0 | L39: =SUM(K39,F39) -> 0 | M39: =L39+J39+AB39 -> 3020.979 | N39: =INT($L39/480)+1 -> 1 | O39: =INT(($M39-0.0001)/480)+1 -> 7 | P39: =IF(N39>MAX('07_Calendario'!$F$5:$F$82),"Fuera del mes",INDEX('07_Calendario'!$B$5:$B$82,MATCH(N39,'07_Calendario'!$F$5:$F$82,0))) -> 46266 | Q39: =IF(O39>MAX('07_Calendario'!$F$5:$F$82),"Fuera del mes",INDEX('07_Calendario'!$B$5:$B$82,MATCH(O39,'07_Calendario'!$F$5:$F$82,0))) -> 46268 | T39: ='02_Datos_Maestros'!$A$18 -> 15881 | U39: ='02_Datos_Maestros'!$I$18 -> 5998 | V39: =MATCH($U39,$C$15:$C$22,0) -> 4 | W39: =COUNTIFS($U$26:$U$42,$U39,$T$26:$T$42,"<="&$T39) -> 2 | X39: =$V39*100+$W39 -> 402 | Y39: =RANK($X39,$X$26:$X$42,1) -> 5 | Z39: =480-MOD(L39,480) -> 480 | AA39: =INT(ROUND(Z39*H39/480,6)) -> 1144 | AB39: =IF(G39>AA39,MAX(0,Z39-AA39*I39),0) -> 0
