Workbook

Sheet Datos
A1: Serie historica - valor mensual
A3: fecha | B3: valor
A4: 2022-08 | B4: 9630.299
A5: 2022-09 | B5: 10251.463
A6: 2022-10 | B6: 9106.906
A7: 2022-11 | B7: 7350.898
A8: 2022-12 | B8: 12285.013
A9: 2023-01 | B9: 7210.104
A10: 2023-02 | B10: 5576.998
A11: 2023-03 | B11: 6648.943
A12: 2023-04 | B12: 8525.213
A13: 2023-05 | B13: 7428.518
A14: 2023-06 | B14: 6618.344
A15: 2023-07 | B15: 10251.381
... A51: 2026-07 | B51: 5205.246

Sheet 1_Simplistas
A1: 1. Modelos Informales o Simplistas: Naive y Naive Estacional
A2: Naive: pronostico(t) = valor(t-1). Naive Estacional: pronostico(t) = valor(t-12) (mismo mes del año anterior).
A4: fecha | B4: real | C4: naive | D4: naive_estacional
A5: 2022-08 | B5: 9630.299
A6: 2022-09 | B6: 10251.463 | C6: =B5 -> 9630.299
A7: 2022-10 | B7: 9106.906 | C7: =B6 -> 10251.463
A8: 2022-11 | B8: 7350.898 | C8: =B7 -> 9106.906
A9: 2022-12 | B9: 12285.013 | C9: =B8 -> 7350.898
A10: 2023-01 | B10: 7210.104 | C10: =B9 -> 12285.013
A11: 2023-02 | B11: 5576.998 | C11: =B10 -> 7210.104
A12: 2023-03 | B12: 6648.943 | C12: =B11 -> 5576.998
A13: 2023-04 | B13: 8525.213 | C13: =B12 -> 6648.943
A14: 2023-05 | B14: 7428.518 | C14: =B13 -> 8525.213
A15: 2023-06 | B15: 6618.344 | C15: =B14 -> 7428.518
A16: 2023-07 | B16: 10251.381 | C16: =B15 -> 6618.344
A17: 2023-08 | B17: 8574.422 | C17: =B16 -> 10251.381 | D17: =B5 -> 9630.299
A18: 2023-09 | B18: 8853.157 | C18: =B17 -> 8574.422 | D18: =B6 -> 10251.463
A19: 2023-10 | B19: 11343.447 | C19: =B18 -> 8853.157 | D19: =B7 -> 9106.906
A20: 2023-11 | B20: 9180.757 | C20: =B19 -> 11343.447 | D20: =B8 -> 7350.898
A21: 2023-12 | B21: 12310.301 | C21: =B20 -> 9180.757 | D21: =B9 -> 12285.013
A22: 2024-01 | B22: 4916.502 | C22: =B21 -> 12310.301 | D22: =B10 -> 7210.104
A23: 2024-02 | B23: 5690.96 | C23: =B22 -> 4916.502 | D23: =B11 -> 5576.998
A24: 2024-03 | B24: 6504.837 | C24: =B23 -> 5690.96 | D24: =B12 -> 6648.943
A25: 2024-04 | B25: 6356.898 | C25: =B24 -> 6504.837 | D25: =B13 -> 8525.213
A26: 2024-05 | B26: 7687.409 | C26: =B25 -> 6356.898 | D26: =B14 -> 7428.518
A27: 2024-06 | B27: 6111.243 | C27: =B26 -> 7687.409 | D27: =B15 -> 6618.344
A28: 2024-07 | B28: 11481.558 | C28: =B27 -> 6111.243 | D28: =B16 -> 10251.381
... A52: 2026-07 | B52: 5205.246 | C52: =B51 -> 5044.84 | D52: =B40 -> 8601.489
A53: 2026-08 | C53: =B52 -> 5205.246 | D53: =B41 -> 4877.567
A54: 2026-09 | C54: =B52 -> 5205.246 | D54: =B42 -> 6672.551
A55: 2026-10 | C55: =B52 -> 5205.246 | D55: =B43 -> 9619.03

Sheet 2_Tendencia_Central
A1: 2. Modelos de Tendencia Central: Promedio Simple y Medias Moviles
A2: Promedio simple acumulado hasta t-1; Media movil de 3 y 12 periodos.
A4: fecha | B4: real | C4: promedio_simple | D4: ma_3 | E4: ma_12
A5: 2022-08 | B5: 9630.299
A6: 2022-09 | B6: 10251.463 | C6: =AVERAGE($B$5:B5) -> 9630.299
A7: 2022-10 | B7: 9106.906 | C7: =AVERAGE($B$5:B6) -> 9940.881
A8: 2022-11 | B8: 7350.898 | C8: =AVERAGE($B$5:B7) -> 9662.8893 | D8: =AVERAGE(B5:B7) -> 9662.8893
A9: 2022-12 | B9: 12285.013 | C9: =AVERAGE($B$5:B8) -> 9084.8915 | D9: =AVERAGE(B6:B8) -> 8903.089
A10: 2023-01 | B10: 7210.104 | C10: =AVERAGE($B$5:B9) -> 9724.9158 | D10: =AVERAGE(B7:B9) -> 9580.939
A11: 2023-02 | B11: 5576.998 | C11: =AVERAGE($B$5:B10) -> 9305.7805 | D11: =AVERAGE(B8:B10) -> 8948.6717
A12: 2023-03 | B12: 6648.943 | C12: =AVERAGE($B$5:B11) -> 8773.0973 | D12: =AVERAGE(B9:B11) -> 8357.3717
A13: 2023-04 | B13: 8525.213 | C13: =AVERAGE($B$5:B12) -> 8507.578 | D13: =AVERAGE(B10:B12) -> 6478.6817
A14: 2023-05 | B14: 7428.518 | C14: =AVERAGE($B$5:B13) -> 8509.5374 | D14: =AVERAGE(B11:B13) -> 6917.0513
A15: 2023-06 | B15: 6618.344 | C15: =AVERAGE($B$5:B14) -> 8401.4355 | D15: =AVERAGE(B12:B14) -> 7534.2247
A16: 2023-07 | B16: 10251.381 | C16: =AVERAGE($B$5:B15) -> 8239.3363 | D16: =AVERAGE(B13:B15) -> 7524.025
A17: 2023-08 | B17: 8574.422 | C17: =AVERAGE($B$5:B16) -> 8407.0067 | D17: =AVERAGE(B14:B16) -> 8099.4143 | E17: =AVERAGE(B5:B16) -> 8407.0067
A18: 2023-09 | B18: 8853.157 | C18: =AVERAGE($B$5:B17) -> 8419.8848 | D18: =AVERAGE(B15:B17) -> 8481.3823 | E18: =AVERAGE(B6:B17) -> 8319.0169
A19: 2023-10 | B19: 11343.447 | C19: =AVERAGE($B$5:B18) -> 8450.8328 | D19: =AVERAGE(B16:B18) -> 9226.32 | E19: =AVERAGE(B7:B18) -> 8202.4914
A20: 2023-11 | B20: 9180.757 | C20: =AVERAGE($B$5:B19) -> 8643.6737 | D20: =AVERAGE(B17:B19) -> 9590.342 | E20: =AVERAGE(B8:B19) -> 8388.8698
A21: 2023-12 | B21: 12310.301 | C21: =AVERAGE($B$5:B20) -> 8677.2414 | D21: =AVERAGE(B18:B20) -> 9792.4537 | E21: =AVERAGE(B9:B20) -> 8541.3581
A22: 2024-01 | B22: 4916.502 | C22: =AVERAGE($B$5:B21) -> 8890.9508 | D22: =AVERAGE(B19:B21) -> 10944.835 | E22: =AVERAGE(B10:B21) -> 8543.4654
A23: 2024-02 | B23: 5690.96 | C23: =AVERAGE($B$5:B22) -> 8670.1481 | D23: =AVERAGE(B20:B22) -> 8802.52 | E23: =AVERAGE(B11:B22) -> 8352.3319
A24: 2024-03 | B24: 6504.837 | C24: =AVERAGE($B$5:B23) -> 8513.3487 | D24: =AVERAGE(B21:B23) -> 7639.2543 | E24: =AVERAGE(B12:B23) -> 8361.8287
A25: 2024-04 | B25: 6356.898 | C25: =AVERAGE($B$5:B24) -> 8412.9232 | D25: =AVERAGE(B22:B24) -> 5704.0997 | E25: =AVERAGE(B13:B24) -> 8349.8199
A26: 2024-05 | B26: 7687.409 | C26: =AVERAGE($B$5:B25) -> 8315.0172 | D26: =AVERAGE(B23:B25) -> 6184.2317 | E26: =AVERAGE(B14:B25) -> 8169.127
A27: 2024-06 | B27: 6111.243 | C27: =AVERAGE($B$5:B26) -> 8286.4895 | D27: =AVERAGE(B24:B26) -> 6849.7147 | E27: =AVERAGE(B15:B26) -> 8190.7012
A28: 2024-07 | B28: 11481.558 | C28: =AVERAGE($B$5:B27) -> 8191.9136 | D28: =AVERAGE(B25:B27) -> 6718.5167 | E28: =AVERAGE(B16:B27) -> 8148.4428
... A52: 2026-07 | B52: 5205.246 | C52: =AVERAGE($B$5:B51) -> 7502.9236 | D52: =AVERAGE(B49:B51) -> 5213.4157 | E52: =AVERAGE(B40:B51) -> 6140.8974
A53: 2026-08 | C53: =AVERAGE($B$5:$B52) -> 7455.0554 | D53: =AVERAGE(B50:B52) -> 5192.3897 | E53: =AVERAGE(B41:B52) -> 5857.8772
A54: 2026-09 | C54: =AVERAGE($B$5:$B52) -> 7455.0554 | D54: =AVERAGE(B50:B52) -> 5192.3897 | E54: =AVERAGE(B41:B52) -> 5857.8772
A55: 2026-10 | C55: =AVERAGE($B$5:$B52) -> 7455.0554 | D55: =AVERAGE(B50:B52) -> 5192.3897 | E55: =AVERAGE(B41:B52) -> 5857.8772

Sheet 3_Suavizacion
A1: 3. Modelos de Suavizacion: SES, Holt y Holt-Winters
A2: SES: alpha=0.50 (calibrado 2024-09 a 2025-06, h=1..3) | Holt: alpha=0.30, beta=0.00 (calibrado 2024-09 a 2025-06) | Holt-Winters: alpha=0.10, beta=0.10, gamma=0.50 (calibrado 2024-09 a 2025-06, estacionalidad=12). Parametros elegidos por calibracion (no por maxima verosimilitud sobre todos los datos). Formulas recursivas auditables desde la fila 80: nivel, tendencia y estacionalidad de cada modelo.
A4: fecha | B4: real | C4: ses | D4: holt | E4: holt_winters
A5: 2022-08 | B5: 9630.299 | C5: =E95 -> 10220.976 | D5: =F95+G95 -> 9890.1501 | E5: =H95+I95+J95 -> 7482.7452
A6: 2022-09 | B6: 10251.463 | C6: =E96 -> 9925.6373 | D6: =F96+G96 -> 9481.3693 | E6: =H96+I96+J96 -> 8655.7814
A7: 2022-10 | B7: 9106.906 | C7: =E97 -> 10088.55 | D7: =F97+G97 -> 9381.5719 | E7: =H97+I97+J97 -> 12016.539
A8: 2022-11 | B8: 7350.898 | C8: =E98 -> 9597.7281 | D8: =F98+G98 -> 8968.3467 | E8: =H98+I98+J98 -> 9158.4865
A9: 2022-12 | B9: 12285.013 | C9: =E99 -> 8474.313 | D9: =F99+G99 -> 8152.2866 | E9: =H99+I99+J99 -> 11994.692
A10: 2023-01 | B10: 7210.104 | C10: =E100 -> 10379.663 | D10: =F100+G100 -> 9061.2791 | E10: =H100+I100+J100 -> 6002.5279
A11: 2023-02 | B11: 5576.998 | C11: =E101 -> 8794.8835 | D11: =F101+G101 -> 8175.1011 | E11: =H101+I101+J101 -> 6006.9448
A12: 2023-03 | B12: 6648.943 | C12: =E102 -> 7185.9408 | D12: =F102+G102 -> 7064.8447 | E12: =H102+I102+J102 -> 7046.6504
A13: 2023-04 | B13: 8525.213 | C13: =E103 -> 6917.4419 | D13: =F103+G103 -> 6609.2487 | E13: =H103+I103+J103 -> 7824.4402
A14: 2023-05 | B14: 7428.518 | C14: =E104 -> 7721.3274 | D14: =F104+G104 -> 6853.2125 | E14: =H104+I104+J104 -> 7647.7463
A15: 2023-06 | B15: 6618.344 | C15: =E105 -> 7574.9227 | D15: =F105+G105 -> 6694.9787 | E15: =H105+I105+J105 -> 6602.5223
A16: 2023-07 | B16: 10251.381 | C16: =E106 -> 7096.6334 | D16: =F106+G106 -> 6341.1628 | E16: =H106+I106+J106 -> 10880.572
... A52: 2026-07 | B52: 5205.246 | C52: =E142 -> 5145.1041 | D52: =F142+G142 -> 4206.3883 | E52: =H142+I142+J142 -> 8036.0053
A53: 2026-08 | C53: =E143 -> 5175.1751 | D53: =F143+1*G143 -> 4175.2201 | E53: =H143+1*I143+J143 -> 4097.8386
A54: 2026-09 | C54: =E143 -> 5175.1751 | D54: =F143+2*G143 -> 3844.3946 | E54: =H143+2*I143+J144 -> 5338.0774
A55: 2026-10 | C55: =E143 -> 5175.1751 | D55: =F143+3*G143 -> 3513.5692 | E55: =H143+3*I143+J145 -> 8211.6209
A80: Parametros y estado inicial (para auditar SES / Holt / Holt-Winters)
A81: SES alpha | B81: 0.5
A82: SES nivel inicial (L0) | B82: 10220.976
A83: Holt alpha | B83: 0.3
A84: Holt beta | B84: 0
A85: Holt nivel inicial (L0) | B85: 10220.976
A86: Holt tendencia inicial (T0) | B86: -330.82547
A87: HW alpha | B87: 0.1
A88: HW beta | B88: 0.1
A89: HW gamma | B89: 0.5
A90: HW nivel inicial (L0) | B90: 8411.8743
A91: HW tendencia inicial (T0) | B91: -10.755996
A94: Estacional inicial HW (S0) | D94: Estado interno (k=0 = antes de la primera observacion)
A95: 1 | B95: -918.37315 | D95: 0 | E95: =$B$82 -> 10220.976 | F95: =$B$85 -> 10220.976 | G95: =$B$86 -> -330.82547 | H95: =$B$90 -> 8411.8743 | I95: =$B$91 -> -10.755996 | J95: =B95 -> -918.37315
A96: 2 | B96: 29.188169 | D96: 1 | E96: =$B$81*B5+(1-$B$81)*E95 -> 9925.6373 | F96: =$B$83*B5+(1-$B$83)*(F95+G95) -> 9812.1948 | G96: =$B$84*(F96-F95)+(1-$B$84)*G95 -> -330.82547 | H96: =$B$87*(B5-J95)+(1-$B$87)*(H95+I95) -> 8615.8737 | I96: =$B$88*(H96-H95)+(1-$B$88)*I95 -> 10.719542 | J96: =B96 -> 29.188169
A97: 3 | B97: 3203.7008 | D97: 2 | E97: =$B$81*B6+(1-$B$81)*E96 -> 10088.55 | F97: =$B$83*B6+(1-$B$83)*(F96+G96) -> 9712.3974 | G97: =$B$84*(F97-F96)+(1-$B$84)*G96 -> -330.82547 | H97: =$B$87*(B6-J96)+(1-$B$87)*(H96+I96) -> 8786.1614 | I97: =$B$88*(H97-H96)+(1-$B$88)*I96 -> 26.676358 | J97: =B97 -> 3203.7008
A98: 4 | B98: 639.03195 | D98: 3 | E98: =$B$81*B7+(1-$B$81)*E97 -> 9597.7281 | F98: =$B$83*B7+(1-$B$83)*(F97+G97) -> 9299.1722 | G98: =$B$84*(F98-F97)+(1-$B$84)*G97 -> -330.82547 | H98: =$B$87*(B7-J97)+(1-$B$87)*(H97+I97) -> 8521.8745 | I98: =$B$88*(H98-H97)+(1-$B$88)*I97 -> -2.4199668 | J98: =B98 -> 639.03195
A99: 5 | B99: 3676.4918 | D99: 4 | E99: =$B$81*B8+(1-$B$81)*E98 -> 8474.313 | F99: =$B$83*B8+(1-$B$83)*(F98+G98) -> 8483.1121 | G99: =$B$84*(F99-F98)+(1-$B$84)*G98 -> -330.82547 | H99: =$B$87*(B8-J98)+(1-$B$87)*(H98+I98) -> 8338.6957 | I99: =$B$88*(H99-H98)+(1-$B$88)*I98 -> -20.495852 | J99: =B99 -> 3676.4918
A100: 6 | B100: -2327.1115 | D100: 5 | E100: =$B$81*B9+(1-$B$81)*E99 -> 10379.663 | F100: =$B$83*B9+(1-$B$83)*(F99+G99) -> 9392.1045 | G100: =$B$84*(F100-F99)+(1-$B$84)*G99 -> -330.82547 | H100: =$B$87*(B9-J99)+(1-$B$87)*(H99+I99) -> 8347.232 | I100: =$B$88*(H100-H99)+(1-$B$88)*I99 -> -17.592638 | J100: =B100 -> -2327.1115
A101: 7 | B101: -2437.9353 | D101: 6 | E101: =$B$81*B10+(1-$B$81)*E100 -> 8794.8835 | F101: =$B$83*B10+(1-$B$83)*(F100+G100) -> 8505.9265 | G101: =$B$84*(F101-F100)+(1-$B$84)*G100 -> -330.82547 | H101: =$B$87*(B10-J100)+(1-$B$87)*(H100+I100) -> 8450.3969 | I101: =$B$88*(H101-H100)+(1-$B$88)*I100 -> -5.5168762 | J101: =B101 -> -2437.9353
A102: 8 | B102: -1345.4187 | D102: 7 | E102: =$B$81*B11+(1-$B$81)*E101 -> 7185.9408 | F102: =$B$83*B11+(1-$B$83)*(F101+G101) -> 7395.6701 | G102: =$B$84*(F102-F101)+(1-$B$84)*G101 -> -330.82547 | H102: =$B$87*(B11-J101)+(1-$B$87)*(H101+I101) -> 8401.8854 | I102: =$B$88*(H102-H101)+(1-$B$88)*I101 -> -9.8163443 | J102: =B102 -> -1345.4187
...

Sheet 4_Regresion
A1: 4. Modelo de Regresion Lineal (tendencia + estacionalidad mensual)
A2: valor = b0 + b1*t + suma(bm*mes_m), mes de referencia = Enero. Coeficientes:
D3: fecha | E3: real | F3: regresion
A4: Intercepto (Ene) | B4: 7175.6692 | D4: 2022-08 | E4: 9630.299 | F4: =$B$4+$B$5*1+IF(VALUE(MID(D4,6,2))=1,0,INDEX($B$6:$B$16,VALUE(MID(D4,6,2))-1)) -> 8653.5314
A5: Tendencia (t) | B5: -71.6164 | D5: 2022-09 | E5: 10251.463 | F5: =$B$4+$B$5*2+IF(VALUE(MID(D5,6,2))=1,0,INDEX($B$6:$B$16,VALUE(MID(D5,6,2))-1)) -> 9484.1456
A6: Dummy Feb | B6: -405.7141 | D6: 2022-10 | E6: 9106.906 | F6: =$B$4+$B$5*3+IF(VALUE(MID(D6,6,2))=1,0,INDEX($B$6:$B$16,VALUE(MID(D6,6,2))-1)) -> 11531.332
A7: Dummy Mar | B7: 860.4363 | D7: 2022-11 | E7: 7350.898 | F7: =$B$4+$B$5*4+IF(VALUE(MID(D7,6,2))=1,0,INDEX($B$6:$B$16,VALUE(MID(D7,6,2))-1)) -> 9113.0121
A8: Dummy Abr | B8: 1505.6664 | D8: 2022-12 | E8: 12285.013 | F8: =$B$4+$B$5*5+IF(VALUE(MID(D8,6,2))=1,0,INDEX($B$6:$B$16,VALUE(MID(D8,6,2))-1)) -> 12586.355
A9: Dummy May | B9: 1416.8183 | D9: 2023-01 | E9: 7210.104 | F9: =$B$4+$B$5*6+IF(VALUE(MID(D9,6,2))=1,0,INDEX($B$6:$B$16,VALUE(MID(D9,6,2))-1)) -> 6745.9708
A10: Dummy Jun | B10: 608.6272 | D10: 2023-02 | E10: 5576.998 | F10: =$B$4+$B$5*7+IF(VALUE(MID(D10,6,2))=1,0,INDEX($B$6:$B$16,VALUE(MID(D10,6,2))-1)) -> 6268.6403
A11: Dummy Jul | B11: 3857.7408 | D11: 2023-03 | E11: 6648.943 | F11: =$B$4+$B$5*8+IF(VALUE(MID(D11,6,2))=1,0,INDEX($B$6:$B$16,VALUE(MID(D11,6,2))-1)) -> 7463.1743
A12: Dummy Ago | B12: 1549.4786 | D12: 2023-04 | E12: 8525.213 | F12: =$B$4+$B$5*9+IF(VALUE(MID(D12,6,2))=1,0,INDEX($B$6:$B$16,VALUE(MID(D12,6,2))-1)) -> 8036.788
A13: Dummy Sep | B13: 2451.7092 | D13: 2023-05 | E13: 7428.518 | F13: =$B$4+$B$5*10+IF(VALUE(MID(D13,6,2))=1,0,INDEX($B$6:$B$16,VALUE(MID(D13,6,2))-1)) -> 7876.3235
A14: Dummy Oct | B14: 4570.5116 | D14: 2023-06 | E14: 6618.344 | F14: =$B$4+$B$5*11+IF(VALUE(MID(D14,6,2))=1,0,INDEX($B$6:$B$16,VALUE(MID(D14,6,2))-1)) -> 6996.516
A15: Dummy Nov | B15: 2223.8085 | D15: 2023-07 | E15: 10251.381 | F15: =$B$4+$B$5*12+IF(VALUE(MID(D15,6,2))=1,0,INDEX($B$6:$B$16,VALUE(MID(D15,6,2))-1)) -> 10174.013
A16: Dummy Dic | B16: 5768.7679 | D16: 2023-08 | E16: 8574.422 | F16: =$B$4+$B$5*13+IF(VALUE(MID(D16,6,2))=1,0,INDEX($B$6:$B$16,VALUE(MID(D16,6,2))-1)) -> 7794.1346
D17: 2023-09 | E17: 8853.157 | F17: =$B$4+$B$5*14+IF(VALUE(MID(D17,6,2))=1,0,INDEX($B$6:$B$16,VALUE(MID(D17,6,2))-1)) -> 8624.7488
D18: 2023-10 | E18: 11343.447 | F18: =$B$4+$B$5*15+IF(VALUE(MID(D18,6,2))=1,0,INDEX($B$6:$B$16,VALUE(MID(D18,6,2))-1)) -> 10671.935
D19: 2023-11 | E19: 9180.757 | F19: =$B$4+$B$5*16+IF(VALUE(MID(D19,6,2))=1,0,INDEX($B$6:$B$16,VALUE(MID(D19,6,2))-1)) -> 8253.6153
D20: 2023-12 | E20: 12310.301 | F20: =$B$4+$B$5*17+IF(VALUE(MID(D20,6,2))=1,0,INDEX($B$6:$B$16,VALUE(MID(D20,6,2))-1)) -> 11726.958
D21: 2024-01 | E21: 4916.502 | F21: =$B$4+$B$5*18+IF(VALUE(MID(D21,6,2))=1,0,INDEX($B$6:$B$16,VALUE(MID(D21,6,2))-1)) -> 5886.574
D22: 2024-02 | E22: 5690.96 | F22: =$B$4+$B$5*19+IF(VALUE(MID(D22,6,2))=1,0,INDEX($B$6:$B$16,VALUE(MID(D22,6,2))-1)) -> 5409.2435
D23: 2024-03 | E23: 6504.837 | F23: =$B$4+$B$5*20+IF(VALUE(MID(D23,6,2))=1,0,INDEX($B$6:$B$16,VALUE(MID(D23,6,2))-1)) -> 6603.7775
D24: 2024-04 | E24: 6356.898 | F24: =$B$4+$B$5*21+IF(VALUE(MID(D24,6,2))=1,0,INDEX($B$6:$B$16,VALUE(MID(D24,6,2))-1)) -> 7177.3912
D25: 2024-05 | E25: 7687.409 | F25: =$B$4+$B$5*22+IF(VALUE(MID(D25,6,2))=1,0,INDEX($B$6:$B$16,VALUE(MID(D25,6,2))-1)) -> 7016.9267
D26: 2024-06 | E26: 6111.243 | F26: =$B$4+$B$5*23+IF(VALUE(MID(D26,6,2))=1,0,INDEX($B$6:$B$16,VALUE(MID(D26,6,2))-1)) -> 6137.1192
D27: 2024-07 | E27: 11481.558 | F27: =$B$4+$B$5*24+IF(VALUE(MID(D27,6,2))=1,0,INDEX($B$6:$B$16,VALUE(MID(D27,6,2))-1)) -> 9314.6164
D28: 2024-08 | E28: 6375.458 | F28: =$B$4+$B$5*25+IF(VALUE(MID(D28,6,2))=1,0,INDEX($B$6:$B$16,VALUE(MID(D28,6,2))-1)) -> 6934.7378
D29: 2024-09 | E29: 7003.032 | F29: =$B$4+$B$5*26+IF(VALUE(MID(D29,6,2))=1,0,INDEX($B$6:$B$16,VALUE(MID(D29,6,2))-1)) -> 7765.352
D30: 2024-10 | E30: 10899.564 | F30: =$B$4+$B$5*27+IF(VALUE(MID(D30,6,2))=1,0,INDEX($B$6:$B$16,VALUE(MID(D30,6,2))-1)) -> 9812.538
D31: 2024-11 | E31: 7461.092 | F31: =$B$4+$B$5*28+IF(VALUE(MID(D31,6,2))=1,0,INDEX($B$6:$B$16,VALUE(MID(D31,6,2))-1)) -> 7394.2185
D32: 2024-12 | E32: 12917.157 | F32: =$B$4+$B$5*29+IF(VALUE(MID(D32,6,2))=1,0,INDEX($B$6:$B$16,VALUE(MID(D32,6,2))-1)) -> 10867.561
D33: 2025-01 | E33: 5233.063 | F33: =$B$4+$B$5*30+IF(VALUE(MID(D33,6,2))=1,0,INDEX($B$6:$B$16,VALUE(MID(D33,6,2))-1)) -> 5027.1772
D34: 2025-02 | E34: 5157.814 | F34: =$B$4+$B$5*31+IF(VALUE(MID(D34,6,2))=1,0,INDEX($B$6:$B$16,VALUE(MID(D34,6,2))-1)) -> 4549.8467
D35: 2025-03 | E35: 6202.39 | F35: =$B$4+$B$5*32+IF(VALUE(MID(D35,6,2))=1,0,INDEX($B$6:$B$16,VALUE(MID(D35,6,2))-1)) -> 5744.3807
D36: 2025-04 | E36: 6840.338 | F36: =$B$4+$B$5*33+IF(VALUE(MID(D36,6,2))=1,0,INDEX($B$6:$B$16,VALUE(MID(D36,6,2))-1)) -> 6317.9944
D37: 2025-05 | E37: 5905.905 | F37: =$B$4+$B$5*34+IF(VALUE(MID(D37,6,2))=1,0,INDEX($B$6:$B$16,VALUE(MID(D37,6,2))-1)) -> 6157.5299
D38: 2025-06 | E38: 5055.258 | F38: =$B$4+$B$5*35+IF(VALUE(MID(D38,6,2))=1,0,INDEX($B$6:$B$16,VALUE(MID(D38,6,2))-1)) -> 5277.7224
D39: 2025-07 | E39: 8601.489 | F39: =$B$4+$B$5*36+IF(VALUE(MID(D39,6,2))=1,0,INDEX($B$6:$B$16,VALUE(MID(D39,6,2))-1)) -> 8455.2196
D40: 2025-08 | E40: 4877.567 | F40: =$B$4+$B$5*37+IF(VALUE(MID(D40,6,2))=1,0,INDEX($B$6:$B$16,VALUE(MID(D40,6,2))-1)) -> 6075.341
...

Sheet 5_ARIMA
A1: 5. Modelo ARIMA/SARIMA
A2: SARIMA(0, 1, 1)x(1, 1, 1, 12), orden elegido por AIC en 2022-08 a 2025-06. Ajustado en Python (statsmodels); valores e intervalo de confianza 95% pegados.
A4: fecha | B4: real | C4: ajustado | D4: pronostico | E4: ic_inferior | F4: ic_superior
A5: 2022-08 | B5: 9630.299
A6: 2022-09 | B6: 10251.463 | C6: 9630.299
A7: 2022-10 | B7: 9106.906 | C7: 10042.965
A8: 2022-11 | B8: 7350.898 | C8: 9363.875
A9: 2022-12 | B9: 12285.013 | C9: 7894.383
A10: 2023-01 | B10: 7210.104 | C10: 11101.032
A11: 2023-02 | B11: 5576.998 | C11: 8259.242
A12: 2023-03 | B12: 6648.943 | C12: 6300.225
A13: 2023-04 | B13: 8525.213 | C13: 6554.916
A14: 2023-05 | B14: 7428.518 | C14: 7993.952
A15: 2023-06 | B15: 6618.344 | C15: 7580.979
A16: 2023-07 | B16: 10251.381 | C16: 6877.904
A17: 2023-08 | B17: 8574.422 | C17: 16640.507
... A52: 2026-07 | B52: 5205.246 | C52: 6844.47
A53: 2026-08 | D53: 4873.235 | E53: 2685.514 | F53: 7060.957
A54: 2026-09 | D54: 5613.202 | E54: 3426.402 | F54: 7800.002
A55: 2026-10 | D55: 7573.324 | E55: 5391.959 | F55: 9754.689

Sheet Resumen_Comparativo
A1: Resumen Comparativo de Modelos
A2: Validacion cruzada de origen movil: 10 origenes de evaluacion (2025-07 a 2026-04), pronosticando h=1,2,3 meses (30 pares pronostico-real por modelo). Hiperparametros de SES/Holt/Holt-Winters/SARIMA calibrados aparte, en 10 origenes previos (2024-09 a 2025-06), minimizando error de pronostico fuera de muestra.
A4: Modelo | B4: MAE | C4: RMSE | D4: MAPE (%) | E4: WAPE (%) | F4: F-ACC (%)
A5: Naive | B5: 1840.12 | C5: 2340.69 | D5: 34.64 | E5: 30.84 | F5: 69.16
A6: Naive Estacional | B6: 1398.16 | C6: 2017.5 | D6: 24.08 | E6: 23.43 | F6: 76.57
A7: Promedio Simple | B7: 2199.45 | C7: 2500.72 | D7: 45.11 | E7: 36.86 | F7: 63.14
A8: Media Movil (3) | B8: 1552.42 | C8: 2096.35 | D8: 31.04 | E8: 26.02 | F8: 73.98
A9: Media Movil (12) | B9: 1444.63 | C9: 1723.61 | D9: 28.84 | E9: 24.21 | F9: 75.79
A10: SES (Suavizacion Exponencial Simple) | B10: 1479.82 | C10: 2016.79 | D10: 29.1 | E10: 24.8 | F10: 75.2
A11: Holt (doble) | B11: 1723.91 | C11: 2067.16 | D11: 28.87 | E11: 28.89 | F11: 71.11
A12: Holt-Winters (triple) | B12: 914.95 | C12: 1410.84 | D12: 15.25 | E12: 15.33 | F12: 84.67
A13: Regresion Lineal | B13: 902.19 | C13: 1394.67 | D13: 14.77 | E13: 15.12 | F13: 84.88
A14: SARIMA | B14: 1176.67 | C14: 1608.11 | D14: 20.93 | E14: 19.72 | F14: 80.28
A17: Pronostico Ago-Sep-Oct 2026 por modelo
A19: Modelo | B19: 2026-08 | C19: 2026-09 | D19: 2026-10
A20: Naive | B20: ='1_Simplistas'!C53 -> 5205.246 | C20: ='1_Simplistas'!C54 -> 5205.246 | D20: ='1_Simplistas'!C55 -> 5205.246
A21: Naive Estacional | B21: ='1_Simplistas'!D53 -> 4877.567 | C21: ='1_Simplistas'!D54 -> 6672.551 | D21: ='1_Simplistas'!D55 -> 9619.03
A22: Promedio Simple | B22: ='2_Tendencia_Central'!C53 -> 7455.0554 | C22: ='2_Tendencia_Central'!C54 -> 7455.0554 | D22: ='2_Tendencia_Central'!C55 -> 7455.0554
A23: Media Movil (3) | B23: ='2_Tendencia_Central'!D53 -> 5192.3897 | C23: ='2_Tendencia_Central'!D54 -> 5192.3897 | D23: ='2_Tendencia_Central'!D55 -> 5192.3897
A24: Media Movil (12) | B24: ='2_Tendencia_Central'!E53 -> 5857.8772 | C24: ='2_Tendencia_Central'!E54 -> 5857.8772 | D24: ='2_Tendencia_Central'!E55 -> 5857.8772
A25: SES (Suavizacion Exponencial Simple) | B25: ='3_Suavizacion'!C53 -> 5175.1751 | C25: ='3_Suavizacion'!C54 -> 5175.1751 | D25: ='3_Suavizacion'!C55 -> 5175.1751
A26: Holt (doble) | B26: ='3_Suavizacion'!D53 -> 4175.2201 | C26: ='3_Suavizacion'!D54 -> 3844.3946 | D26: ='3_Suavizacion'!D55 -> 3513.5692
A27: Holt-Winters (triple) | B27: ='3_Suavizacion'!E53 -> 4097.8386 | C27: ='3_Suavizacion'!E54 -> 5338.0774 | D27: ='3_Suavizacion'!E55 -> 8211.6209
A28: Regresion Lineal | B28: ='4_Regresion'!F52 -> 5215.9442 | C28: ='4_Regresion'!F53 -> 6046.5584 | D28: ='4_Regresion'!F54 -> 8093.7444
A29: SARIMA | B29: ='5_ARIMA'!D53 -> 4873.235 | C29: ='5_ARIMA'!D54 -> 5613.202 | D29: ='5_ARIMA'!D55 -> 7573.324
A32: Historico reciente + pronosticos (grafico)
A33: fecha | B33: real | C33: Naive | D33: Naive Estacional | E33: Promedio Simple | F33: Media Movil (3) | G33: Media Movil (12) | H33: SES (Suavizacion Exponencial Simple) | I33: Holt (doble) | J33: Holt-Winters (triple) | K33: Regresion Lineal | L33: SARIMA
A34: 2025-08 | B34: 4877.567
A35: 2025-09 | B35: 6672.551
A36: 2025-10 | B36: 9619.03
A37: 2025-11 | B37: 7302.922
A38: 2025-12 | B38: 7676.57
A39: 2026-01 | B39: 4467.835
A40: 2026-02 | B40: 3492.41
A41: 2026-03 | B41: 5340.148
A42: 2026-04 | B42: 5268.324
A43: 2026-05 | B43: 5327.083
A44: 2026-06 | B44: 5044.84
A45: 2026-07 | B45: 5205.246
A46: 2026-08 | C46: ='1_Simplistas'!C53 -> 5205.246 | D46: ='1_Simplistas'!D53 -> 4877.567 | E46: ='2_Tendencia_Central'!C53 -> 7455.0554 | F46: ='2_Tendencia_Central'!D53 -> 5192.3897 | G46: ='2_Tendencia_Central'!E53 -> 5857.8772 | H46: ='3_Suavizacion'!C53 -> 5175.1751 | I46: ='3_Suavizacion'!D53 -> 4175.2201 | J46: ='3_Suavizacion'!E53 -> 4097.8386 | K46: ='4_Regresion'!F52 -> 5215.9442 | L46: ='5_ARIMA'!D53 -> 4873.235
...
